Workbook

Sheet Tổng quan
A1: NexaTicket — Báo cáo kiểm thử
A2: Sinh tự động ngày 23/10/2026 00:54 từ kết quả chạy thật. Các tổng bên dưới là công thức.
A4: 1. Kết quả thực thi theo tầng
A5: Hệ / Tầng | B5: Tổng | C5: Đạt | D5: Đỏ | E5: Bỏ qua | F5: Tỉ lệ đạt
A6: Backend — Unit | B6: =COUNTIFS('Danh mục test tự động'!$B$5:$B$4102,"Backend",'Danh mục test tự động'!$D$5:$D$4102,"Unit") | C6: =COUNTIFS('Danh mục test tự động'!$B$5:$B$4102,"Backend",'Danh mục test tự động'!$D$5:$D$4102,"Unit",'Danh mục test tự động'!$I$5:$I$4102,"Đạt") | D6: =COUNTIFS('Danh mục test tự động'!$B$5:$B$4102,"Backend",'Danh mục test tự động'!$D$5:$D$4102,"Unit",'Danh mục test tự động'!$I$5:$I$4102,"Đỏ") | E6: =COUNTIFS('Danh mục test tự động'!$B$5:$B$4102,"Backend",'Danh mục test tự động'!$D$5:$D$4102,"Unit",'Danh mục test tự động'!$I$5:$I$4102,"Bỏ qua") | F6: =IF(B6=0,"-",C6/B6)
A7: Backend — API slice | B7: =COUNTIFS('Danh mục test tự động'!$B$5:$B$4102,"Backend",'Danh mục test tự động'!$D$5:$D$4102,"API slice") | C7: =COUNTIFS('Danh mục test tự động'!$B$5:$B$4102,"Backend",'Danh mục test tự động'!$D$5:$D$4102,"API slice",'Danh mục test tự động'!$I$5:$I$4102,"Đạt") | D7: =COUNTIFS('Danh mục test tự động'!$B$5:$B$4102,"Backend",'Danh mục test tự động'!$D$5:$D$4102,"API slice",'Danh mục test tự động'!$I$5:$I$4102,"Đỏ") | E7: =COUNTIFS('Danh mục test tự động'!$B$5:$B$4102,"Backend",'Danh mục test tự động'!$D$5:$D$4102,"API slice",'Danh mục test tự động'!$I$5:$I$4102,"Bỏ qua") | F7: =IF(B7=0,"-",C7/B7)
A8: Backend — ArchUnit | B8: =COUNTIFS('Danh mục test tự động'!$B$5:$B$4102,"Backend",'Danh mục test tự động'!$D$5:$D$4102,"ArchUnit") | C8: =COUNTIFS('Danh mục test tự động'!$B$5:$B$4102,"Backend",'Danh mục test tự động'!$D$5:$D$4102,"ArchUnit",'Danh mục test tự động'!$I$5:$I$4102,"Đạt") | D8: =COUNTIFS('Danh mục test tự động'!$B$5:$B$4102,"Backend",'Danh mục test tự động'!$D$5:$D$4102,"ArchUnit",'Danh mục test tự động'!$I$5:$I$4102,"Đỏ") | E8: =COUNTIFS('Danh mục test tự động'!$B$5:$B$4102,"Backend",'Danh mục test tự động'!$D$5:$D$4102,"ArchUnit",'Danh mục test tự động'!$I$5:$I$4102,"Bỏ qua") | F8: =IF(B8=0,"-",C8/B8)
A9: Backend — Integration | B9: =COUNTIFS('Danh mục test tự động'!$B$5:$B$4102,"Backend",'Danh mục test tự động'!$D$5:$D$4102,"Integration") | C9: =COUNTIFS('Danh mục test tự động'!$B$5:$B$4102,"Backend",'Danh mục test tự động'!$D$5:$D$4102,"Integration",'Danh mục test tự động'!$I$5:$I$4102,"Đạt") | D9: =COUNTIFS('Danh mục test tự động'!$B$5:$B$4102,"Backend",'Danh mục test tự động'!$D$5:$D$4102,"Integration",'Danh mục test tự động'!$I$5:$I$4102,"Đỏ") | E9: =COUNTIFS('Danh mục test tự động'!$B$5:$B$4102,"Backend",'Danh mục test tự động'!$D$5:$D$4102,"Integration",'Danh mục test tự động'!$I$5:$I$4102,"Bỏ qua") | F9: =IF(B9=0,"-",C9/B9)
A10: Frontend — Unit | B10: =COUNTIFS('Danh mục test tự động'!$B$5:$B$4102,"Frontend",'Danh mục test tự động'!$D$5:$D$4102,"Unit") | C10: =COUNTIFS('Danh mục test tự động'!$B$5:$B$4102,"Frontend",'Danh mục test tự động'!$D$5:$D$4102,"Unit",'Danh mục test tự động'!$I$5:$I$4102,"Đạt") | D10: =COUNTIFS('Danh mục test tự động'!$B$5:$B$4102,"Frontend",'Danh mục test tự động'!$D$5:$D$4102,"Unit",'Danh mục test tự động'!$I$5:$I$4102,"Đỏ") | E10: =COUNTIFS('Danh mục test tự động'!$B$5:$B$4102,"Frontend",'Danh mục test tự động'!$D$5:$D$4102,"Unit",'Danh mục test tự động'!$I$5:$I$4102,"Bỏ qua") | F10: =IF(B10=0,"-",C10/B10)
A11: Frontend — E2E | B11: =COUNTIFS('Danh mục test tự động'!$B$5:$B$4102,"Frontend",'Danh mục test tự động'!$D$5:$D$4102,"E2E") | C11: =COUNTIFS('Danh mục test tự động'!$B$5:$B$4102,"Frontend",'Danh mục test tự động'!$D$5:$D$4102,"E2E",'Danh mục test tự động'!$I$5:$I$4102,"Đạt") | D11: =COUNTIFS('Danh mục test tự động'!$B$5:$B$4102,"Frontend",'Danh mục test tự động'!$D$5:$D$4102,"E2E",'Danh mục test tự động'!$I$5:$I$4102,"Đỏ") | E11: =COUNTIFS('Danh mục test tự động'!$B$5:$B$4102,"Frontend",'Danh mục test tự động'!$D$5:$D$4102,"E2E",'Danh mục test tự động'!$I$5:$I$4102,"Bỏ qua") | F11: =IF(B11=0,"-",C11/B11)
A12: TỔNG | B12: =SUM(B6:B11) | C12: =SUM(C6:C11) | D12: =SUM(D6:D11) | E12: =SUM(E6:E11) | F12: =IF(B12=0,"-",C12/B12)
A14: 2. Coverage backend (JaCoCo, unit + integration gộp)
A15: Chỉ số | B15: Hiện tại | C15: Mục tiêu | D15: Đạt mục tiêu?
A16: Dòng (line) | B16: ='Coverage backend'!J23 | C16: 0.8 | D16: =IF(B16>=C16,"Đạt","Chưa đạt")
A17: Nhánh (branch) | B17: ='Coverage backend'!G23 | C17: 0.8 | D17: =IF(B17>=C17,"Đạt","Chưa đạt")
A18: Câu lệnh (instruction) | B18: ='Coverage backend'!D23 | C18: 0.8 | D18: =IF(B18>=C18,"Đạt","Chưa đạt")
A19: Phương thức (method) | B19: ='Coverage backend'!M23 | C19: 0.8 | D19: =IF(B19>=C19,"Đạt","Chưa đạt")
A20: Mục tiêu 80% là ngưỡng của đề bài (ô xanh có thể sửa); các tỉ lệ là công thức từ sheet 'Coverage backend'.
A22: 3. Tài sản kiểm thử
A23: Ca kiểm thử chức năng (sheet 'Test case chức năng') | B23: =COUNTA('Test case chức năng'!A5:A79)
A24: Endpoint API đã ánh xạ tới test (sheet 'Ma trận API') | B24: =COUNTA('Ma trận API'!A5:A185)
A25: Endpoint API CHƯA có test nào | B25: =COUNTIF('Ma trận API'!F5:F185,"")
A26: Test tự động (sheet 'Danh mục test tự động') | B26: =COUNTA('Danh mục test tự động'!$A$5:$A$4102)
A28: 4. Phạm vi và giới hạn (trung thực)
A29: • k6: hold-contention đạt 4/4 lần (đúng 1 người thắng trong 4 người tranh một nhóm ghế); discovery chạy ổn nhưng vượt ba ngưỡng độ trễ và làm inventory hết bộ nhớ ở heap 384 MB (docs/03-seat-checkout/load-test-report.md). checkout.js chạy với payOS giả (load-tests/fake-payos) đạt 68 vòng, 279/279 checks; payOS thật chưa kiểm.
A30: • App mobile (4 app React Native) nằm ngoài phạm vi đợt này.
A31: • E2E dùng nhà phát hành OIDC giả; đăng nhập Keycloak thật, trang payOS (không có sandbox), realtime chưa kiểm được.
A32: • Coverage frontend thấp ở app web-customer / web-admin vì Vitest tính mọi tệp, kể cả trang chưa test (xem sheet 'Coverage frontend').
A33: • Chi tiết lỗi đã sửa và khoảng trống: sheet 'Lỗi đã sửa', 'Khoảng trống'.

Sheet Kết quả theo module
A1: Kết quả theo module
A2: Đếm bằng công thức COUNTIFS trên sheet 'Danh mục test tự động'.
A4: Hệ | B4: Module | C4: Tổng | D4: Đạt | E4: Đỏ | F4: Bỏ qua | G4: Unit + slice + ArchUnit | H4: Integration / E2E
A5: Backend | B5: ai-chatbox-service | C5: =COUNTIFS('Danh mục test tự động'!$B$5:$B$4102,$A5,'Danh mục test tự động'!$C$5:$C$4102,$B5) | D5: =COUNTIFS('Danh mục test tự động'!$B$5:$B$4102,$A5,'Danh mục test tự động'!$C$5:$C$4102,$B5,'Danh mục test tự động'!$I$5:$I$4102,"Đạt") | E5: =COUNTIFS('Danh mục test tự động'!$B$5:$B$4102,$A5,'Danh mục test tự động'!$C$5:$C$4102,$B5,'Danh mục test tự động'!$I$5:$I$4102,"Đỏ") | F5: =COUNTIFS('Danh mục test tự động'!$B$5:$B$4102,$A5,'Danh mục test tự động'!$C$5:$C$4102,$B5,'Danh mục test tự động'!$I$5:$I$4102,"Bỏ qua") | G5: =COUNTIFS('Danh mục test tự động'!$B$5:$B$4102,$A5,'Danh mục test tự động'!$C$5:$C$4102,$B5,'Danh mục test tự động'!$D$5:$D$4102,"Unit")+COUNTIFS('Danh mục test tự động'!$B$5:$B$4102,$A5,'Danh mục test tự động'!$C$5:$C$4102,$B5,'Danh mục test tự động'!$D$5:$D$4102,"API slice")+COUNTIFS('Danh mục test tự động'!$B$5:$B$4102,$A5,'Danh mục test tự động'!$C$5:$C$4102,$B5,'Danh mục test tự động'!$D$5:$D$4102,"ArchUnit") | H5: =COUNTIFS('Danh mục test tự động'!$B$5:$B$4102,$A5,'Danh mục test tự động'!$C$5:$C$4102,$B5,'Danh mục test tự động'!$D$5:$D$4102,"Integration")+COUNTIFS('Danh mục test tự động'!$B$5:$B$4102,$A5,'Danh mục test tự động'!$C$5:$C$4102,$B5,'Danh mục test tự động'!$D$5:$D$4102,"E2E")
A6: Backend | B6: analytics-service | C6: =COUNTIFS('Danh mục test tự động'!$B$5:$B$4102,$A6,'Danh mục test tự động'!$C$5:$C$4102,$B6) | D6: =COUNTIFS('Danh mục test tự động'!$B$5:$B$4102,$A6,'Danh mục test tự động'!$C$5:$C$4102,$B6,'Danh mục test tự động'!$I$5:$I$4102,"Đạt") | E6: =COUNTIFS('Danh mục test tự động'!$B$5:$B$4102,$A6,'Danh mục test tự động'!$C$5:$C$4102,$B6,'Danh mục test tự động'!$I$5:$I$4102,"Đỏ") | F6: =COUNTIFS('Danh mục test tự động'!$B$5:$B$4102,$A6,'Danh mục test tự động'!$C$5:$C$4102,$B6,'Danh mục test tự động'!$I$5:$I$4102,"Bỏ qua") | G6: =COUNTIFS('Danh mục test tự động'!$B$5:$B$4102,$A6,'Danh mục test tự động'!$C$5:$C$4102,$B6,'Danh mục test tự động'!$D$5:$D$4102,"Unit")+COUNTIFS('Danh mục test tự động'!$B$5:$B$4102,$A6,'Danh mục test tự động'!$C$5:$C$4102,$B6,'Danh mục test tự động'!$D$5:$D$4102,"API slice")+COUNTIFS('Danh mục test tự động'!$B$5:$B$4102,$A6,'Danh mục test tự động'!$C$5:$C$4102,$B6,'Danh mục test tự động'!$D$5:$D$4102,"ArchUnit") | H6: =COUNTIFS('Danh mục test tự động'!$B$5:$B$4102,$A6,'Danh mục test tự động'!$C$5:$C$4102,$B6,'Danh mục test tự động'!$D$5:$D$4102,"Integration")+COUNTIFS('Danh mục test tự động'!$B$5:$B$4102,$A6,'Danh mục test tự động'!$C$5:$C$4102,$B6,'Danh mục test tự động'!$D$5:$D$4102,"E2E")
A7: Backend | B7: api-gateway | C7: =COUNTIFS('Danh mục test tự động'!$B$5:$B$4102,$A7,'Danh mục test tự động'!$C$5:$C$4102,$B7) | D7: =COUNTIFS('Danh mục test tự động'!$B$5:$B$4102,$A7,'Danh mục test tự động'!$C$5:$C$4102,$B7,'Danh mục test tự động'!$I$5:$I$4102,"Đạt") | E7: =COUNTIFS('Danh mục test tự động'!$B$5:$B$4102,$A7,'Danh mục test tự động'!$C$5:$C$4102,$B7,'Danh mục test tự động'!$I$5:$I$4102,"Đỏ") | F7: =COUNTIFS('Danh mục test tự động'!$B$5:$B$4102,$A7,'Danh mục test tự động'!$C$5:$C$4102,$B7,'Danh mục test tự động'!$I$5:$I$4102,"Bỏ qua") | G7: =COUNTIFS('Danh mục test tự động'!$B$5:$B$4102,$A7,'Danh mục test tự động'!$C$5:$C$4102,$B7,'Danh mục test tự động'!$D$5:$D$4102,"Unit")+COUNTIFS('Danh mục test tự động'!$B$5:$B$4102,$A7,'Danh mục test tự động'!$C$5:$C$4102,$B7,'Danh mục test tự động'!$D$5:$D$4102,"API slice")+COUNTIFS('Danh mục test tự động'!$B$5:$B$4102,$A7,'Danh mục test tự động'!$C$5:$C$4102,$B7,'Danh mục test tự động'!$D$5:$D$4102,"ArchUnit") | H7: =COUNTIFS('Danh mục test tự động'!$B$5:$B$4102,$A7,'Danh mục test tự động'!$C$5:$C$4102,$B7,'Danh mục test tự động'!$D$5:$D$4102,"Integration")+COUNTIFS('Danh mục test tự động'!$B$5:$B$4102,$A7,'Danh mục test tự động'!$C$5:$C$4102,$B7,'Danh mục test tự động'!$D$5:$D$4102,"E2E")
A8: Backend | B8: catalog-service | C8: =COUNTIFS('Danh mục test tự động'!$B$5:$B$4102,$A8,'Danh mục test tự động'!$C$5:$C$4102,$B8) | D8: =COUNTIFS('Danh mục test tự động'!$B$5:$B$4102,$A8,'Danh mục test tự động'!$C$5:$C$4102,$B8,'Danh mục test tự động'!$I$5:$I$4102,"Đạt") | E8: =COUNTIFS('Danh mục test tự động'!$B$5:$B$4102,$A8,'Danh mục test tự động'!$C$5:$C$4102,$B8,'Danh mục test tự động'!$I$5:$I$4102,"Đỏ") | F8: =COUNTIFS('Danh mục test tự động'!$B$5:$B$4102,$A8,'Danh mục test tự động'!$C$5:$C$4102,$B8,'Danh mục test tự động'!$I$5:$I$4102,"Bỏ qua") | G8: =COUNTIFS('Danh mục test tự động'!$B$5:$B$4102,$A8,'Danh mục test tự động'!$C$5:$C$4102,$B8,'Danh mục test tự động'!$D$5:$D$4102,"Unit")+COUNTIFS('Danh mục test tự động'!$B$5:$B$4102,$A8,'Danh mục test tự động'!$C$5:$C$4102,$B8,'Danh mục test tự động'!$D$5:$D$4102,"API slice")+COUNTIFS('Danh mục test tự động'!$B$5:$B$4102,$A8,'Danh mục test tự động'!$C$5:$C$4102,$B8,'Danh mục test tự động'!$D$5:$D$4102,"ArchUnit") | H8: =COUNTIFS('Danh mục test tự động'!$B$5:$B$4102,$A8,'Danh mục test tự động'!$C$5:$C$4102,$B8,'Danh mục test tự động'!$D$5:$D$4102,"Integration")+COUNTIFS('Danh mục test tự động'!$B$5:$B$4102,$A8,'Danh mục test tự động'!$C$5:$C$4102,$B8,'Danh mục test tự động'!$D$5:$D$4102,"E2E")
A9: Backend | B9: identity-service | C9: =COUNTIFS('Danh mục test tự động'!$B$5:$B$4102,$A9,'Danh mục test tự động'!$C$5:$C$4102,$B9) | D9: =COUNTIFS('Danh mục test tự động'!$B$5:$B$4102,$A9,'Danh mục test tự động'!$C$5:$C$4102,$B9,'Danh mục test tự động'!$I$5:$I$4102,"Đạt") | E9: =COUNTIFS('Danh mục test tự động'!$B$5:$B$4102,$A9,'Danh mục test tự động'!$C$5:$C$4102,$B9,'Danh mục test tự động'!$I$5:$I$4102,"Đỏ") | F9: =COUNTIFS('Danh mục test tự động'!$B$5:$B$4102,$A9,'Danh mục test tự động'!$C$5:$C$4102,$B9,'Danh mục test tự động'!$I$5:$I$4102,"Bỏ qua") | G9: =COUNTIFS('Danh mục test tự động'!$B$5:$B$4102,$A9,'Danh mục test tự động'!$C$5:$C$4102,$B9,'Danh mục test tự động'!$D$5:$D$4102,"Unit")+COUNTIFS('Danh mục test tự động'!$B$5:$B$4102,$A9,'Danh mục test tự động'!$C$5:$C$4102,$B9,'Danh mục test tự động'!$D$5:$D$4102,"API slice")+COUNTIFS('Danh mục test tự động'!$B$5:$B$4102,$A9,'Danh mục test tự động'!$C$5:$C$4102,$B9,'Danh mục test tự động'!$D$5:$D$4102,"ArchUnit") | H9: =COUNTIFS('Danh mục test tự động'!$B$5:$B$4102,$A9,'Danh mục test tự động'!$C$5:$C$4102,$B9,'Danh mục test tự động'!$D$5:$D$4102,"Integration")+COUNTIFS('Danh mục test tự động'!$B$5:$B$4102,$A9,'Danh mục test tự động'!$C$5:$C$4102,$B9,'Danh mục test tự động'!$D$5:$D$4102,"E2E")
A10: Backend | B10: inventory-service | C10: =COUNTIFS('Danh mục test tự động'!$B$5:$B$4102,$A10,'Danh mục test tự động'!$C$5:$C$4102,$B10) | D10: =COUNTIFS('Danh mục test tự động'!$B$5:$B$4102,$A10,'Danh mục test tự động'!$C$5:$C$4102,$B10,'Danh mục test tự động'!$I$5:$I$4102,"Đạt") | E10: =COUNTIFS('Danh mục test tự động'!$B$5:$B$4102,$A10,'Danh mục test tự động'!$C$5:$C$4102,$B10,'Danh mục test tự động'!$I$5:$I$4102,"Đỏ") | F10: =COUNTIFS('Danh mục test tự động'!$B$5:$B$4102,$A10,'Danh mục test tự động'!$C$5:$C$4102,$B10,'Danh mục test tự động'!$I$5:$I$4102,"Bỏ qua") | G10: =COUNTIFS('Danh mục test tự động'!$B$5:$B$4102,$A10,'Danh mục test tự động'!$C$5:$C$4102,$B10,'Danh mục test tự động'!$D$5:$D$4102,"Unit")+COUNTIFS('Danh mục test tự động'!$B$5:$B$4102,$A10,'Danh mục test tự động'!$C$5:$C$4102,$B10,'Danh mục test tự động'!$D$5:$D$4102,"API slice")+COUNTIFS('Danh mục test tự động'!$B$5:$B$4102,$A10,'Danh mục test tự động'!$C$5:$C$4102,$B10,'Danh mục test tự động'!$D$5:$D$4102,"ArchUnit") | H10: =COUNTIFS('Danh mục test tự động'!$B$5:$B$4102,$A10,'Danh mục test tự động'!$C$5:$C$4102,$B10,'Danh mục test tự động'!$D$5:$D$4102,"Integration")+COUNTIFS('Danh mục test tự động'!$B$5:$B$4102,$A10,'Danh mục test tự động'!$C$5:$C$4102,$B10,'Danh mục test tự động'!$D$5:$D$4102,"E2E")
A11: Backend | B11: ledger-service | C11: =COUNTIFS('Danh mục test tự động'!$B$5:$B$4102,$A11,'Danh mục test tự động'!$C$5:$C$4102,$B11) | D11: =COUNTIFS('Danh mục test tự động'!$B$5:$B$4102,$A11,'Danh mục test tự động'!$C$5:$C$4102,$B11,'Danh mục test tự động'!$I$5:$I$4102,"Đạt") | E11: =COUNTIFS('Danh mục test tự động'!$B$5:$B$4102,$A11,'Danh mục test tự động'!$C$5:$C$4102,$B11,'Danh mục test tự động'!$I$5:$I$4102,"Đỏ") | F11: =COUNTIFS('Danh mục test tự động'!$B$5:$B$4102,$A11,'Danh mục test tự động'!$C$5:$C$4102,$B11,'Danh mục test tự động'!$I$5:$I$4102,"Bỏ qua") | G11: =COUNTIFS('Danh mục test tự động'!$B$5:$B$4102,$A11,'Danh mục test tự động'!$C$5:$C$4102,$B11,'Danh mục test tự động'!$D$5:$D$4102,"Unit")+COUNTIFS('Danh mục test tự động'!$B$5:$B$4102,$A11,'Danh mục test tự động'!$C$5:$C$4102,$B11,'Danh mục test tự động'!$D$5:$D$4102,"API slice")+COUNTIFS('Danh mục test tự động'!$B$5:$B$4102,$A11,'Danh mục test tự động'!$C$5:$C$4102,$B11,'Danh mục test tự động'!$D$5:$D$4102,"ArchUnit") | H11: =COUNTIFS('Danh mục test tự động'!$B$5:$B$4102,$A11,'Danh mục test tự động'!$C$5:$C$4102,$B11,'Danh mục test tự động'!$D$5:$D$4102,"Integration")+COUNTIFS('Danh mục test tự động'!$B$5:$B$4102,$A11,'Danh mục test tự động'!$C$5:$C$4102,$B11,'Danh mục test tự động'!$D$5:$D$4102,"E2E")
A12: Backend | B12: notification-service | C12: =COUNTIFS('Danh mục test tự động'!$B$5:$B$4102,$A12,'Danh mục test tự động'!$C$5:$C$4102,$B12) | D12: =COUNTIFS('Danh mục test tự động'!$B$5:$B$4102,$A12,'Danh mục test tự động'!$C$5:$C$4102,$B12,'Danh mục test tự động'!$I$5:$I$4102,"Đạt") | E12: =COUNTIFS('Danh mục test tự động'!$B$5:$B$4102,$A12,'Danh mục test tự động'!$C$5:$C$4102,$B12,'Danh mục test tự động'!$I$5:$I$4102,"Đỏ") | F12: =COUNTIFS('Danh mục test tự động'!$B$5:$B$4102,$A12,'Danh mục test tự động'!$C$5:$C$4102,$B12,'Danh mục test tự động'!$I$5:$I$4102,"Bỏ qua") | G12: =COUNTIFS('Danh mục test tự động'!$B$5:$B$4102,$A12,'Danh mục test tự động'!$C$5:$C$4102,$B12,'Danh mục test tự động'!$D$5:$D$4102,"Unit")+COUNTIFS('Danh mục test tự động'!$B$5:$B$4102,$A12,'Danh mục test tự động'!$C$5:$C$4102,$B12,'Danh mục test tự động'!$D$5:$D$4102,"API slice")+COUNTIFS('Danh mục test tự động'!$B$5:$B$4102,$A12,'Danh mục test tự động'!$C$5:$C$4102,$B12,'Danh mục test tự động'!$D$5:$D$4102,"ArchUnit") | H12: =COUNTIFS('Danh mục test tự động'!$B$5:$B$4102,$A12,'Danh mục test tự động'!$C$5:$C$4102,$B12,'Danh mục test tự động'!$D$5:$D$4102,"Integration")+COUNTIFS('Danh mục test tự động'!$B$5:$B$4102,$A12,'Danh mục test tự động'!$C$5:$C$4102,$B12,'Danh mục test tự động'!$D$5:$D$4102,"E2E")
A13: Backend | B13: ordering-service | C13: =COUNTIFS('Danh mục test tự động'!$B$5:$B$4102,$A13,'Danh mục test tự động'!$C$5:$C$4102,$B13) | D13: =COUNTIFS('Danh mục test tự động'!$B$5:$B$4102,$A13,'Danh mục test tự động'!$C$5:$C$4102,$B13,'Danh mục test tự động'!$I$5:$I$4102,"Đạt") | E13: =COUNTIFS('Danh mục test tự động'!$B$5:$B$4102,$A13,'Danh mục test tự động'!$C$5:$C$4102,$B13,'Danh mục test tự động'!$I$5:$I$4102,"Đỏ") | F13: =COUNTIFS('Danh mục test tự động'!$B$5:$B$4102,$A13,'Danh mục test tự động'!$C$5:$C$4102,$B13,'Danh mục test tự động'!$I$5:$I$4102,"Bỏ qua") | G13: =COUNTIFS('Danh mục test tự động'!$B$5:$B$4102,$A13,'Danh mục test tự động'!$C$5:$C$4102,$B13,'Danh mục test tự động'!$D$5:$D$4102,"Unit")+COUNTIFS('Danh mục test tự động'!$B$5:$B$4102,$A13,'Danh mục test tự động'!$C$5:$C$4102,$B13,'Danh mục test tự động'!$D$5:$D$4102,"API slice")+COUNTIFS('Danh mục test tự động'!$B$5:$B$4102,$A13,'Danh mục test tự động'!$C$5:$C$4102,$B13,'Danh mục test tự động'!$D$5:$D$4102,"ArchUnit") | H13: =COUNTIFS('Danh mục test tự động'!$B$5:$B$4102,$A13,'Danh mục test tự động'!$C$5:$C$4102,$B13,'Danh mục test tự động'!$D$5:$D$4102,"Integration")+COUNTIFS('Danh mục test tự động'!$B$5:$B$4102,$A13,'Danh mục test tự động'!$C$5:$C$4102,$B13,'Danh mục test tự động'!$D$5:$D$4102,"E2E")
A14: Backend | B14: payment-service | C14: =COUNTIFS('Danh mục test tự động'!$B$5:$B$4102,$A14,'Danh mục test tự động'!$C$5:$C$4102,$B14) | D14: =COUNTIFS('Danh mục test tự động'!$B$5:$B$4102,$A14,'Danh mục test tự động'!$C$5:$C$4102,$B14,'Danh mục test tự động'!$I$5:$I$4102,"Đạt") | E14: =COUNTIFS('Danh mục test tự động'!$B$5:$B$4102,$A14,'Danh mục test tự động'!$C$5:$C$4102,$B14,'Danh mục test tự động'!$I$5:$I$4102,"Đỏ") | F14: =COUNTIFS('Danh mục test tự động'!$B$5:$B$4102,$A14,'Danh mục test tự động'!$C$5:$C$4102,$B14,'Danh mục test tự động'!$I$5:$I$4102,"Bỏ qua") | G14: =COUNTIFS('Danh mục test tự động'!$B$5:$B$4102,$A14,'Danh mục test tự động'!$C$5:$C$4102,$B14,'Danh mục test tự động'!$D$5:$D$4102,"Unit")+COUNTIFS('Danh mục test tự động'!$B$5:$B$4102,$A14,'Danh mục test tự động'!$C$5:$C$4102,$B14,'Danh mục test tự động'!$D$5:$D$4102,"API slice")+COUNTIFS('Danh mục test tự động'!$B$5:$B$4102,$A14,'Danh mục test tự động'!$C$5:$C$4102,$B14,'Danh mục test tự động'!$D$5:$D$4102,"ArchUnit") | H14: =COUNTIFS('Danh mục test tự động'!$B$5:$B$4102,$A14,'Danh mục test tự động'!$C$5:$C$4102,$B14,'Danh mục test tự động'!$D$5:$D$4102,"Integration")+COUNTIFS('Danh mục test tự động'!$B$5:$B$4102,$A14,'Danh mục test tự động'!$C$5:$C$4102,$B14,'Danh mục test tự động'!$D$5:$D$4102,"E2E")
A15: Backend | B15: payout-service | C15: =COUNTIFS('Danh mục test tự động'!$B$5:$B$4102,$A15,'Danh mục test tự động'!$C$5:$C$4102,$B15) | D15: =COUNTIFS('Danh mục test tự động'!$B$5:$B$4102,$A15,'Danh mục test tự động'!$C$5:$C$4102,$B15,'Danh mục test tự động'!$I$5:$I$4102,"Đạt") | E15: =COUNTIFS('Danh mục test tự động'!$B$5:$B$4102,$A15,'Danh mục test tự động'!$C$5:$C$4102,$B15,'Danh mục test tự động'!$I$5:$I$4102,"Đỏ") | F15: =COUNTIFS('Danh mục test tự động'!$B$5:$B$4102,$A15,'Danh mục test tự động'!$C$5:$C$4102,$B15,'Danh mục test tự động'!$I$5:$I$4102,"Bỏ qua") | G15: =COUNTIFS('Danh mục test tự động'!$B$5:$B$4102,$A15,'Danh mục test tự động'!$C$5:$C$4102,$B15,'Danh mục test tự động'!$D$5:$D$4102,"Unit")+COUNTIFS('Danh mục test tự động'!$B$5:$B$4102,$A15,'Danh mục test tự động'!$C$5:$C$4102,$B15,'Danh mục test tự động'!$D$5:$D$4102,"API slice")+COUNTIFS('Danh mục test tự động'!$B$5:$B$4102,$A15,'Danh mục test tự động'!$C$5:$C$4102,$B15,'Danh mục test tự động'!$D$5:$D$4102,"ArchUnit") | H15: =COUNTIFS('Danh mục test tự động'!$B$5:$B$4102,$A15,'Danh mục test tự động'!$C$5:$C$4102,$B15,'Danh mục test tự động'!$D$5:$D$4102,"Integration")+COUNTIFS('Danh mục test tự động'!$B$5:$B$4102,$A15,'Danh mục test tự động'!$C$5:$C$4102,$B15,'Danh mục test tự động'!$D$5:$D$4102,"E2E")
A16: Backend | B16: realtime-gateway | C16: =COUNTIFS('Danh mục test tự động'!$B$5:$B$4102,$A16,'Danh mục test tự động'!$C$5:$C$4102,$B16) | D16: =COUNTIFS('Danh mục test tự động'!$B$5:$B$4102,$A16,'Danh mục test tự động'!$C$5:$C$4102,$B16,'Danh mục test tự động'!$I$5:$I$4102,"Đạt") | E16: =COUNTIFS('Danh mục test tự động'!$B$5:$B$4102,$A16,'Danh mục test tự động'!$C$5:$C$4102,$B16,'Danh mục test tự động'!$I$5:$I$4102,"Đỏ") | F16: =COUNTIFS('Danh mục test tự động'!$B$5:$B$4102,$A16,'Danh mục test tự động'!$C$5:$C$4102,$B16,'Danh mục test tự động'!$I$5:$I$4102,"Bỏ qua") | G16: =COUNTIFS('Danh mục test tự động'!$B$5:$B$4102,$A16,'Danh mục test tự động'!$C$5:$C$4102,$B16,'Danh mục test tự động'!$D$5:$D$4102,"Unit")+COUNTIFS('Danh mục test tự động'!$B$5:$B$4102,$A16,'Danh mục test tự động'!$C$5:$C$4102,$B16,'Danh mục test tự động'!$D$5:$D$4102,"API slice")+COUNTIFS('Danh mục test tự động'!$B$5:$B$4102,$A16,'Danh mục test tự động'!$C$5:$C$4102,$B16,'Danh mục test tự động'!$D$5:$D$4102,"ArchUnit") | H16: =COUNTIFS('Danh mục test tự động'!$B$5:$B$4102,$A16,'Danh mục test tự động'!$C$5:$C$4102,$B16,'Danh mục test tự động'!$D$5:$D$4102,"Integration")+COUNTIFS('Danh mục test tự động'!$B$5:$B$4102,$A16,'Danh mục test tự động'!$C$5:$C$4102,$B16,'Danh mục test tự động'!$D$5:$D$4102,"E2E")
... A30: Frontend | B30: web-scanner | C30: =COUNTIFS('Danh mục test tự động'!$B$5:$B$4102,$A30,'Danh mục test tự động'!$C$5:$C$4102,$B30) | D30: =COUNTIFS('Danh mục test tự động'!$B$5:$B$4102,$A30,'Danh mục test tự động'!$C$5:$C$4102,$B30,'Danh mục test tự động'!$I$5:$I$4102,"Đạt") | E30: =COUNTIFS('Danh mục test tự động'!$B$5:$B$4102,$A30,'Danh mục test tự động'!$C$5:$C$4102,$B30,'Danh mục test tự động'!$I$5:$I$4102,"Đỏ") | F30: =COUNTIFS('Danh mục test tự động'!$B$5:$B$4102,$A30,'Danh mục test tự động'!$C$5:$C$4102,$B30,'Danh mục test tự động'!$I$5:$I$4102,"Bỏ qua") | G30: =COUNTIFS('Danh mục test tự động'!$B$5:$B$4102,$A30,'Danh mục test tự động'!$C$5:$C$4102,$B30,'Danh mục test tự động'!$D$5:$D$4102,"Unit")+COUNTIFS('Danh mục test tự động'!$B$5:$B$4102,$A30,'Danh mục test tự động'!$C$5:$C$4102,$B30,'Danh mục test tự động'!$D$5:$D$4102,"API slice")+COUNTIFS('Danh mục test tự động'!$B$5:$B$4102,$A30,'Danh mục test tự động'!$C$5:$C$4102,$B30,'Danh mục test tự động'!$D$5:$D$4102,"ArchUnit") | H30: =COUNTIFS('Danh mục test tự động'!$B$5:$B$4102,$A30,'Danh mục test tự động'!$C$5:$C$4102,$B30,'Danh mục test tự động'!$D$5:$D$4102,"Integration")+COUNTIFS('Danh mục test tự động'!$B$5:$B$4102,$A30,'Danh mục test tự động'!$C$5:$C$4102,$B30,'Danh mục test tự động'!$D$5:$D$4102,"E2E")
A31: TỔNG | C31: =SUM(C5:C30) | D31: =SUM(D5:D30) | E31: =SUM(E5:E30) | F31: =SUM(F5:F30) | G31: =SUM(G5:G30) | H31: =SUM(H5:H30)

Sheet Coverage backend
A1: Coverage backend — JaCoCo (unit + integration gộp)
A2: Số dòng/nhánh bỏ sót và đã phủ lấy từ jacoco.csv; tỉ lệ là công thức. Loại trừ: lớp *Application và infrastructure/seed.
A4: Module | B4: Instr. bỏ sót | C4: Instr. đã phủ | D4: Instr. % | E4: Nhánh bỏ sót | F4: Nhánh đã phủ | G4: Nhánh % | H4: Dòng bỏ sót | I4: Dòng đã phủ | J4: Dòng % | K4: Method bỏ sót | L4: Method đã phủ | M4: Method %
A5: shared-kernel | B5: 1 | C5: 708 | D5: =IF(B5+C5=0,"-",C5/(B5+C5)) | E5: 1 | F5: 43 | G5: =IF(E5+F5=0,"-",F5/(E5+F5)) | H5: 0 | I5: 107 | J5: =IF(H5+I5=0,"-",I5/(H5+I5)) | K5: 0 | L5: 44 | M5: =IF(K5+L5=0,"-",L5/(K5+L5))
A6: starter-idempotency | B6: 118 | C6: 773 | D6: =IF(B6+C6=0,"-",C6/(B6+C6)) | E6: 12 | F6: 68 | G6: =IF(E6+F6=0,"-",F6/(E6+F6)) | H6: 30 | I6: 155 | J6: =IF(H6+I6=0,"-",I6/(H6+I6)) | K6: 12 | L6: 36 | M6: =IF(K6+L6=0,"-",L6/(K6+L6))
A7: starter-outbox | B7: 22 | C7: 366 | D7: =IF(B7+C7=0,"-",C7/(B7+C7)) | E7: 2 | F7: 16 | G7: =IF(E7+F7=0,"-",F7/(E7+F7)) | H7: 6 | I7: 77 | J7: =IF(H7+I7=0,"-",I7/(H7+I7)) | K7: 3 | L7: 10 | M7: =IF(K7+L7=0,"-",L7/(K7+L7))
A8: starter-security | B8: 253 | C8: 938 | D8: =IF(B8+C8=0,"-",C8/(B8+C8)) | E8: 19 | F8: 137 | G8: =IF(E8+F8=0,"-",F8/(E8+F8)) | H8: 51 | I8: 209 | J8: =IF(H8+I8=0,"-",I8/(H8+I8)) | K8: 17 | L8: 53 | M8: =IF(K8+L8=0,"-",L8/(K8+L8))
A9: starter-web | B9: 28 | C9: 872 | D9: =IF(B9+C9=0,"-",C9/(B9+C9)) | E9: 7 | F9: 71 | G9: =IF(E9+F9=0,"-",F9/(E9+F9)) | H9: 8 | I9: 181 | J9: =IF(H9+I9=0,"-",I9/(H9+I9)) | K9: 4 | L9: 46 | M9: =IF(K9+L9=0,"-",L9/(K9+L9))
A10: ai-chatbox-service | B10: 252 | C10: 12022 | D10: =IF(B10+C10=0,"-",C10/(B10+C10)) | E10: 75 | F10: 819 | G10: =IF(E10+F10=0,"-",F10/(E10+F10)) | H10: 46 | I10: 2427 | J10: =IF(H10+I10=0,"-",I10/(H10+I10)) | K10: 4 | L10: 491 | M10: =IF(K10+L10=0,"-",L10/(K10+L10))
A11: analytics-service | B11: 25 | C11: 679 | D11: =IF(B11+C11=0,"-",C11/(B11+C11)) | E11: 1 | F11: 20 | G11: =IF(E11+F11=0,"-",F11/(E11+F11)) | H11: 3 | I11: 138 | J11: =IF(H11+I11=0,"-",I11/(H11+I11)) | K11: 2 | L11: 42 | M11: =IF(K11+L11=0,"-",L11/(K11+L11))
A12: api-gateway | B12: 0 | C12: 289 | D12: =IF(B12+C12=0,"-",C12/(B12+C12)) | E12: 0 | F12: 8 | G12: =IF(E12+F12=0,"-",F12/(E12+F12)) | H12: 0 | I12: 61 | J12: =IF(H12+I12=0,"-",I12/(H12+I12)) | K12: 0 | L12: 20 | M12: =IF(K12+L12=0,"-",L12/(K12+L12))
A13: catalog-service | B13: 1638 | C13: 11604 | D13: =IF(B13+C13=0,"-",C13/(B13+C13)) | E13: 165 | F13: 516 | G13: =IF(E13+F13=0,"-",F13/(E13+F13)) | H13: 314 | I13: 2230 | J13: =IF(H13+I13=0,"-",I13/(H13+I13)) | K13: 77 | L13: 543 | M13: =IF(K13+L13=0,"-",L13/(K13+L13))
A14: identity-service | B14: 1189 | C14: 8988 | D14: =IF(B14+C14=0,"-",C14/(B14+C14)) | E14: 117 | F14: 435 | G14: =IF(E14+F14=0,"-",F14/(E14+F14)) | H14: 250 | I14: 1889 | J14: =IF(H14+I14=0,"-",I14/(H14+I14)) | K14: 53 | L14: 420 | M14: =IF(K14+L14=0,"-",L14/(K14+L14))
A15: inventory-service | B15: 195 | C15: 4904 | D15: =IF(B15+C15=0,"-",C15/(B15+C15)) | E15: 14 | F15: 204 | G15: =IF(E15+F15=0,"-",F15/(E15+F15)) | H15: 41 | I15: 968 | J15: =IF(H15+I15=0,"-",I15/(H15+I15)) | K15: 11 | L15: 247 | M15: =IF(K15+L15=0,"-",L15/(K15+L15))
A16: ledger-service | B16: 48 | C16: 1431 | D16: =IF(B16+C16=0,"-",C16/(B16+C16)) | E16: 10 | F16: 58 | G16: =IF(E16+F16=0,"-",F16/(E16+F16)) | H16: 12 | I16: 303 | J16: =IF(H16+I16=0,"-",I16/(H16+I16)) | K16: 2 | L16: 81 | M16: =IF(K16+L16=0,"-",L16/(K16+L16))
... A22: ticketing-service | B22: 1252 | C22: 9062 | D22: =IF(B22+C22=0,"-",C22/(B22+C22)) | E22: 95 | F22: 356 | G22: =IF(E22+F22=0,"-",F22/(E22+F22)) | H22: 226 | I22: 1703 | J22: =IF(H22+I22=0,"-",I22/(H22+I22)) | K22: 59 | L22: 406 | M22: =IF(K22+L22=0,"-",L22/(K22+L22))
A23: TỔNG | B23: =SUM(B5:B22) | C23: =SUM(C5:C22) | D23: =IF(B23+C23=0,"-",C23/(B23+C23)) | E23: =SUM(E5:E22) | F23: =SUM(F5:F22) | G23: =IF(E23+F23=0,"-",F23/(E23+F23)) | H23: =SUM(H5:H22) | I23: =SUM(I5:I22) | J23: =IF(H23+I23=0,"-",I23/(H23+I23)) | K23: =SUM(K5:K22) | L23: =SUM(L5:L22) | M23: =IF(K23+L23=0,"-",L23/(K23+L23))
A25: Ô màu vàng = dưới mục tiêu 80%. Module thấp nhất: ai-chatbox-service (adapter LLM cần mạng/model thật), catalog-service (nhánh).

Sheet Coverage frontend
A1: Coverage frontend — @vitest/coverage-v8
A2: Số liệu từ coverage-summary.json của từng gói (đã là phần trăm, nhập nguyên văn).
A4: Gói / app | B4: Statements % | C4: Branches % | D4: Functions % | E4: Lines % | F4: Đạt 80% lines?
A5: ts-sdk | B5: 0.6786 | C5: 0.9502 | D5: 0.6987 | E5: 0.6786 | F5: =IF(E5>=0.8,"Đạt","Chưa đạt")
A6: ui | B6: 0.6814 | C6: 0.8528 | D6: 0.7758 | E6: 0.6814 | F6: =IF(E6>=0.8,"Đạt","Chưa đạt")
A7: auth | B7: 0.7071 | C7: 0.8698 | D7: 0.8909 | E7: 0.7071 | F7: =IF(E7>=0.8,"Đạt","Chưa đạt")
A8: web-customer | B8: 0.2128 | C8: 0.6539 | D8: 0.3711 | E8: 0.2128 | F8: =IF(E8>=0.8,"Đạt","Chưa đạt")
A9: web-admin | B9: 0.0435 | C9: 0.4326 | D9: 0.1666 | E9: 0.0435 | F9: =IF(E9>=0.8,"Đạt","Chưa đạt")
A10: web-scanner | B10: 0.7342 | C10: 0.8783 | D10: 0.6153 | E10: 0.7342 | F10: =IF(E10>=0.8,"Đạt","Chưa đạt")
A11: web-platform | B11: 0.643 | C11: 0.87 | D11: 0.75 | E11: 0.643 | F11: =IF(E11>=0.8,"Đạt","Chưa đạt")
A13: Ghi chú: coverage của web-customer / web-admin thấp vì Vitest đếm mọi tệp dưới src/ (kể cả trang chưa test). Giao diện được kiểm gián tiếp bằng 33 test E2E, không tính vào số này.

Sheet Test case chức năng
A1: Test case chức năng
A2: Điều kiện → bước → kết quả mong đợi, độ ưu tiên và test tự động thực hiện. P0 = bất biến/mất tiền/lộ dữ liệu · P1 = luồng chính · P2 = biên và lỗi nhập liệu. Tầng: U unit · S API slice · I integration · E E2E · K k6.
A4: ID | B4: Nhóm | C4: Tên ca kiểm thử | D4: Điều kiện tiên quyết | E4: Các bước | F4: Kết quả mong đợi | G4: Ưu tiên | H4: Test tự động thực hiện | I4: Kết quả lần chạy cuối | J4: Ghi chú
A5: INV-01 | B5: Tồn kho và giữ chỗ | C5: Nhiều người tranh cùng một ghế | D5: N luồng cùng POST /holds cho một ghế | E5: — | F5: Đúng 1 thành công (201), còn lại 409; không ghế nào có hai hold ACTIVE | G5: P0 | H5: I SeatHoldConcurrencyIT; K hold-contention.js | I5: Đạt | J5: Phần k6 chưa chạy (không có k6 / không dựng đủ hệ thống); phần còn lại đã chạy.
A6: INV-02 | B6: Tồn kho và giữ chỗ | C6: Backstop chống bán trùng ở DB | D6: Bỏ qua gate Redis, ghi trực tiếp hai hold cùng ghế | E6: — | F6: Unique index uq_hold_item_active từ chối | G6: P0 | H6: I OversellBackstopIT | I6: Đạt
A7: INV-03 | B7: Tồn kho và giữ chỗ | C7: Bỏ giữ chỗ chạy chồng với đặt chỗ | D7: Release và Reserve cùng lúc cho một hold | E7: — | F7: Đúng một bên thắng; ghế RESERVED không bao giờ về AVAILABLE | G7: P0 | H7: I ReleaseReserveRaceIT; U ReleaseHoldHandlerTest, ReserveSeatsHandlerTest | I7: Đạt
A8: INV-04 | B8: Tồn kho và giữ chỗ | C8: Vượt hạn mức mua | D8: Người dùng xin quá maxSeatedPerHold / maxTicketsPerCustomer | E8: — | F8: HOLD_LIMIT_EXCEEDED (400) hoặc CUSTOMER_LIMIT_EXCEEDED (409), không giữ gì | G8: P1 | H8: U PurchaseLimitsTest, PlaceHoldHandlerTest | I8: Đạt
A9: INV-05 | B9: Tồn kho và giữ chỗ | C9: Số lượng sai | D9: quantity ≤ 0, thiếu zone, trùng zone | E9: — | F9: 400; trùng zone được gộp | G9: P2 | H9: U HoldRequestTest; S HoldControllerTest | I9: Đạt
A10: INV-06 | B10: Tồn kho và giữ chỗ | C10: Hết hạn giữ chỗ | D10: Hold quá expiresAt | E10: — | F10: Worker nhả ghế đúng một lần, bump version, xoá khoá Redis | G10: P0 | H10: U ExpireHoldsJobTest; I HoldLifecycleIT | I10: Đạt
A11: INV-07 | B11: Tồn kho và giữ chỗ | C11: Redis gate chết | D11: Gate ném lỗi | E11: — | F11: 503 retryable, không giữ chỉ bằng DB | G11: P1 | H11: U PlaceHoldHandlerTest, RedisAvailabilityGateTest | I11: Đạt
A12: INV-08 | B12: Tồn kho và giữ chỗ | C12: Người khác bỏ hold của mình | D12: DELETE /holds/{id} bởi user khác | E12: — | F12: 404 (không xác nhận hold có thật) | G12: P0 | H12: U ReleaseHoldHandlerTest; S HoldControllerTest | I12: Đạt
A13: INV-09 | B13: Tồn kho và giữ chỗ | C13: Message hỏng không làm kẹt hàng đợi | D13: order.paid có orderId không phải UUID; session.published thiếu limits | E13: — | F13: Ack + log, không ném | G13: P0 | H13: U OrderListenersTest, SessionPublishedListenerTest | I13: Đạt
A14: ORD-01 | B14: Đặt đơn và thanh toán | C14: Giá do server tính | D14: Request chỉ có holdId (+ mã giảm giá) | E14: — | F14: Tổng = Σ giá ghế từ Catalog − giảm giá; client không gửi được giá | G14: P0 | H14: U PlaceOrderHandlerTest | I14: Đạt
A15: ORD-02 | B15: Đặt đơn và thanh toán | C15: Hoa hồng theo dòng | D15: 3 vé 333.333đ, 5% | E15: — | F15: 49.998đ (không phải 49.999đ); sổ cái cân | G15: P0 | H15: U OrderTest, OrderInvariantsTest | I15: Đạt
A16: ORD-03 | B16: Đặt đơn và thanh toán | C16: Giảm giá chia dòng | D16: Giảm 100đ cho vé 1.000/2.000/0đ | E16: — | F16: Tổng dòng = giảm giá; không dòng nào giảm quá giá; vé 0đ không nhận phần dư | G16: P0 | H16: U PlaceOrderHandlerTest | I16: Đạt
A17: ORD-04 | B17: Đặt đơn và thanh toán | C17: Bấm "Thanh toán" hai lần | D17: Cùng holdId hai lần | E17: — | F17: Trả lại đúng đơn cũ, không mở đơn thứ hai | G17: P0 | H17: U PlaceOrderHandlerTest; I CheckoutSagaIT; K checkout.js; E checkout.spec | I17: Đạt | J17: Phần k6 chưa chạy (không có k6 / không dựng đủ hệ thống); phần còn lại đã chạy.
A18: ORD-05 | B18: Đặt đơn và thanh toán | C18: Dùng holdId của người khác | D18: User B gửi holdId của A | E18: — | F18: 404, không lộ QR / link thanh toán của A | G18: P0 | H18: U PlaceOrderHandlerTest.hold_cua_nguoi_khac_khong_tra_don | I18: Đạt
A19: ORD-06 | B19: Đặt đơn và thanh toán | C19: Inventory / payment hỏng giữa saga | D19: Một bước ném lỗi | E19: — | F19: Bù trừ ngược thứ tự; bù trừ hỏng → COMPENSATION_PENDING, job quét thử lại | G19: P0 | H19: U PlaceOrderHandlerTest, CompensationSweeperTest; I CheckoutSagaIT | I19: Đạt
A20: ORD-07 | B20: Đặt đơn và thanh toán | C20: Máy trạng thái đơn | D20: Mọi OrderStatus × mọi chuyển | E20: — | F20: Chỉ các chuyển hợp lệ; PAID không có đường vào ngoài markPaid | G20: P0 | H20: U OrderStateTransitionTest | I20: Đạt
A21: ORD-08 | B21: Đặt đơn và thanh toán | C21: Xác nhận thanh toán lần hai | D21: markPaid hai lần | E21: — | F21: false, paidAt không đổi | G21: P0 | H21: U OrderTest, ConfirmPaymentHandlerTest | I21: Đạt
A22: ORD-09 | B22: Đặt đơn và thanh toán | C22: Tiền vào muộn sau khi đơn đã đóng | D22: Webhook tới sau ExpireOrdersJob | E22: — | F22: MANUAL_REVIEW, 200 (không 500), không phát vé | G22: P0 | H22: U ConfirmPaymentHandlerTest; I OrderLifecycleIT | I22: Đạt
A23: ORD-10 | B23: Đặt đơn và thanh toán | C23: Xem / huỷ đơn của người khác | D23: GET/POST cancel đơn người khác | E23: — | F23: 404 | G23: P0 | H23: U OrderQueriesTest, CloseOrderFlowTest; S OrderControllerTest | I23: Đạt
A24: ORD-11 | B24: Đặt đơn và thanh toán | C24: Phân trang | D24: limit/offset âm, quá lớn, không phải số | E24: — | F24: Kẹp về [1,100]/≥0; không phải số → 400 | G24: P2 | H24: S OrderControllerTest | I24: Đạt
A25: PAY-01 | B25: Đặt đơn và thanh toán | C25: Chữ ký webhook sai | D25: Sửa một byte của payload đã ký | E25: — | F25: Bị từ chối, không xác nhận gì | G25: P0 | H25: U PayosSignatureEdgeCaseTest; S PayosWebhookControllerWebTest | I25: Đạt
A26: PAY-02 | B26: Đặt đơn và thanh toán | C26: Webhook giao lại | D26: Cùng giao dịch hai lần | E26: — | F26: DUPLICATE, một bộ vé | G26: P0 | H26: U HandlePayosWebhookHandlerTest; I PayosPaymentFlowIT, WebhookEdgeCasesIT | I26: Đạt
A27: PAY-03 | B27: Đặt đơn và thanh toán | C27: Số tiền lệch | D27: Thiếu / thừa tiền | E27: — | F27: Thiếu → AMOUNT_MISMATCH, đơn vẫn chờ; không đánh dấu đã trả | G27: P0 | H27: U ConfirmTransferHandlerTest | I27: Đạt
A28: PAY-04 | B28: Đặt đơn và thanh toán | C28: payOS 5xx | D28: Gateway trả 503 kèm JSON | E28: — | F28: Unavailable (503, thử lại), không Rejected | G28: P1 | H28: U PayosHttpGatewayTest | I28: Đạt
A29: PAY-05 | B29: Đặt đơn và thanh toán | C29: simulate-transfer ở production | D29: PAYMENT_SANDBOX=false | E29: — | F29: Không thể gọi | G29: P0 | H29: U SimulateTransferHandlerTest, PaymentPropertiesTest; S InternalPaymentControllerWebTest | I29: Đạt
... A79: WEB-11 | B79: Frontend và E2E | C79: Giờ trong báo cáo | D79: — | E79: — | F79: Luôn giờ Việt Nam | G79: P1 | H79: U event-report.test.ts | I79: Đạt
A81: Cột 'Kết quả lần chạy cuối' = Đạt vì toàn bộ test tự động trong sheet 'Danh mục test tự động' đạt ở lần chạy cuối (xem sheet 'Tổng quan'); sửa ô này nếu chạy lại và có test đỏ.

Sheet Ma trận API
A1: Ma trận API — mọi endpoint ↔ test
A2: Quét từ mã nguồn mọi *Controller.java (interfaces/rest). Cột 'Test' trống nghĩa là chưa có test nào nhắc tới controller đó.
A4: Dịch vụ | B4: Method | C4: Đường dẫn | D4: Controller | E4: Yêu cầu quyền | F4: Test (slice + integration)
A5: ai-chatbox-service | B5: POST | C5: /v1/chat/agent/sessions/{sessionId}/handoff | D5: SupportChatController | E5: đăng nhập | F5: ChatIdempotencyIT, SupportChatControllerSliceTest, SupportChatControllerTest
A6: ai-chatbox-service | B6: GET | C6: /v1/chat/agent/sessions/{sessionId}/messages | D6: SupportChatController | E6: đăng nhập | F6: ChatIdempotencyIT, SupportChatControllerSliceTest, SupportChatControllerTest
A7: ai-chatbox-service | B7: POST | C7: /v1/chat/agent/support | D7: SupportChatController | E7: đăng nhập | F7: ChatIdempotencyIT, SupportChatControllerSliceTest, SupportChatControllerTest
A8: ai-chatbox-service | B8: GET | C8: /v1/support/handoffs | D8: SupportDeskController | E8: đăng nhập | F8: SupportDeskControllerTest, SupportDeskHandoverTest, SupportDeskPagingTest
A9: ai-chatbox-service | B9: GET | C9: /v1/support/handoffs/{handoffId} | D9: SupportDeskController | E9: đăng nhập | F9: SupportDeskControllerTest, SupportDeskHandoverTest, SupportDeskPagingTest
A10: ai-chatbox-service | B10: POST | C10: /v1/support/handoffs/{handoffId}/claim | D10: SupportDeskController | E10: đăng nhập | F10: SupportDeskControllerTest, SupportDeskHandoverTest, SupportDeskPagingTest
A11: ai-chatbox-service | B11: POST | C11: /v1/support/handoffs/{handoffId}/messages | D11: SupportDeskController | E11: đăng nhập | F11: SupportDeskControllerTest, SupportDeskHandoverTest, SupportDeskPagingTest
A12: ai-chatbox-service | B12: POST | C12: /v1/support/handoffs/{handoffId}/reassign | D12: SupportDeskController | E12: đăng nhập | F12: SupportDeskControllerTest, SupportDeskHandoverTest, SupportDeskPagingTest
A13: ai-chatbox-service | B13: POST | C13: /v1/support/handoffs/{handoffId}/release | D13: SupportDeskController | E13: đăng nhập | F13: SupportDeskControllerTest, SupportDeskHandoverTest, SupportDeskPagingTest
A14: ai-chatbox-service | B14: POST | C14: /v1/support/handoffs/{handoffId}/resolve | D14: SupportDeskController | E14: đăng nhập | F14: SupportDeskControllerTest, SupportDeskHandoverTest, SupportDeskPagingTest
A15: ai-chatbox-service | B15: GET | C15: /v1/support/knowledge/chunks | D15: SupportKnowledgeController | E15: đăng nhập | F15: SupportDeskPagingTest, SupportKnowledgeControllerTest
... A119: identity-service | B119: GET | C119: /v1/roles | D119: AccessController | E119: đăng nhập | F119: MeAndAccessControllerTest, AccessControlIT
A120: identity-service | B120: GET | C120: /v1/staff-accounts/status | D120: StaffAccountStatusController | E120: đăng nhập
A121: inventory-service | B121: POST | C121: /internal/reservations | D121: InternalReservationController | E121: internal | F121: InternalReservationControllerTest
A122: inventory-service | B122: DELETE | C122: /internal/reservations/{orderId} | D122: InternalReservationController | E122: internal | F122: InternalReservationControllerTest
A123: inventory-service | B123: POST | C123: /internal/reservations/{orderId}/settle | D123: InternalReservationController | E123: internal | F123: InternalReservationControllerTest
A124: inventory-service | B124: GET | C124: /internal/sessions/{eventSessionId}/seat-status | D124: InternalSeatStatusController | E124: internal | F124: InternalSeatStatusControllerTest
A125: inventory-service | B125: DELETE | C125: /v1/holds/{holdId} | D125: HoldController | E125: đăng nhập | F125: HoldControllerTest
A126: inventory-service | B126: GET | C126: /v1/organizations/{organizationId}/stats/inventory/stock | D126: OrganizationSeatStatsController | E126: đăng nhập | F126: OrganizationSeatStatsControllerTest
A127: inventory-service | B127: POST | C127: /v1/sessions/{eventSessionId}/holds | D127: HoldController | E127: đăng nhập | F127: HoldControllerTest
A128: inventory-service | B128: GET | C128: /v1/sessions/{eventSessionId}/seats | D128: SeatMapController | E128: đăng nhập | F128: SeatMapCompressionIT, SeatMapControllerTest
A129: ledger-service | B129: GET | C129: /v1/platform/organizations/{organizationId}/balance | D129: PlatformLedgerController | E129: đăng nhập | F129: PlatformLedgerControllerWebTest
A130: ledger-service | B130: GET | C130: /v1/platform/trial-balance | D130: PlatformLedgerController | E130: đăng nhập | F130: PlatformLedgerControllerWebTest
A131: ordering-service | B131: POST | C131: /internal/orders/statuses | D131: InternalOrderController | E131: internal | F131: InternalOrderControllerTest
A132: ordering-service | B132: GET | C132: /internal/orders/{orderId} | D132: InternalOrderController | E132: internal | F132: InternalOrderControllerTest
... A160: ticketing-service | B160: GET | C160: /v1/orders/{orderId}/tickets | D160: MyTicketsController | E160: đăng nhập | F160: TicketReadControllersWebTest
A161: ticketing-service | B161: GET | C161: /v1/organizations/{organizationId}/checkin/events/{eventId}/gates | D161: CheckinShiftController | E161: CATALOG_MANAGE
A162: ticketing-service | B162: POST | C162: /v1/organizations/{organizationId}/checkin/events/{eventId}/gates | D162: CheckinShiftController | E162: CATALOG_MANAGE
A163: ticketing-service | B163: GET | C163: /v1/organizations/{organizationId}/checkin/events/{eventId}/shifts | D163: CheckinShiftController | E163: CATALOG_MANAGE
A164: ticketing-service | B164: DELETE | C164: /v1/organizations/{organizationId}/checkin/gates/{gateId} | D164: CheckinShiftController | E164: CATALOG_MANAGE
A165: ticketing-service | B165: PUT | C165: /v1/organizations/{organizationId}/checkin/gates/{gateId} | D165: CheckinShiftController | E165: CATALOG_MANAGE
A166: ticketing-service | B166: GET | C166: /v1/organizations/{organizationId}/checkin/my-shifts | D166: CheckinShiftController | E166: CHECKIN_SCAN
A167: ticketing-service | B167: POST | C167: /v1/organizations/{organizationId}/checkin/shifts | D167: CheckinShiftController | E167: CATALOG_MANAGE
A168: ticketing-service | B168: DELETE | C168: /v1/organizations/{organizationId}/checkin/shifts/{shiftId} | D168: CheckinShiftController | E168: CATALOG_MANAGE
A169: ticketing-service | B169: PUT | C169: /v1/organizations/{organizationId}/checkin/shifts/{shiftId} | D169: CheckinShiftController | E169: CATALOG_MANAGE
A170: ticketing-service | B170: POST | C170: /v1/organizations/{organizationId}/checkin/shifts/{shiftId}/end | D170: CheckinShiftController | E170: CHECKIN_SCAN
A171: ticketing-service | B171: POST | C171: /v1/organizations/{organizationId}/checkin/shifts/{shiftId}/start | D171: CheckinShiftController | E171: CHECKIN_SCAN
...

Sheet Lỗi đã sửa
A1: Lỗi ứng dụng do test phát hiện và đã sửa
A2: Mỗi lỗi do một test đỏ chỉ ra; sau khi sửa, test giữ lại làm hồi quy.
A4: STT | B4: Lỗi | C4: Cách sửa
A5: 1 | B5: Javadoc nói có filter Idempotency-Key chặn POST thiếu khoá nhưng filter không tồn tại — đặt đơn trùng chỉ dựa vào tra theo holdId và unique index | C5: Hiện thực IdempotencyFilter trong starter-idempotency (bật theo route bằng nexaticket.idempotency.required-paths; áp cho POST /v1/orders và POST /v1/sessions/*/holds): thiếu / sai khoá → 400 IDEMPOTENCY_KEY_REQUIRED; gửi lại cùng khoá và nội dung → phát lại đúng câu trả lời 2xx đã lưu (Idempotent-Replayed: true), handler không chạy lần hai; cùng khoá khác nội dung → 409 IDEMPOTENCY_KEY_REUSED; đang chạy → 409 REQUEST_IN_PROGRESS; handler lỗi → bỏ chỗ giữ để thử lại; bản ghi dở quá 2 phút (tiến trình chết) được nhận lại. Khoá có phạm vi theo người dùng. Kiểm bằng IdempotencyFilterTest (11), IdempotencyFilterIT (4, PostgreSQL thật, gồm 4 luồng song song cùng khoá), OrderIdempotencyIT (5, qua chuỗi bảo mật + saga thật), HoldControllerTest
A6: 2 | B6: Route quét vé cũ POST /v1/sessions/{id}/checkins gắn @RequiresPermission(CHECKIN_SCAN) nhưng đường dẫn không có organizationId nên PermissionGuard từ chối mọi người (ts-sdk.scanTicket còn gọi route này) | C6: Bỏ annotation; quyền CHECKIN_SCAN và việc gán sự kiện vẫn được kiểm trong CheckinAccess.requireScanner theo tổ chức của membership đang hoạt động. Thêm test: chưa được gán → 403 NOT_YOUR_EVENT, khách → 4xx
A7: 3 | B7: Giá catalog ≠ giá tồn kho (25.000đ niêm yết, đơn tính 2.500.000đ): sửa giá hạng vé khi sự kiện đã rút xuống rồi publish lại không đồng bộ giá sang tồn kho — khách thấy một giá, bị tính giá khác | C7: JdbcSessionMaterializer.syncUnsoldPrices đồng bộ giá và tên hạng vé cho chỗ chưa bán (AVAILABLE, BLOCKED, cả đơn vị ảo vé đứng); chỗ đã bán / đang giữ giữ giá cũ. MaterializeSessionIT.publish_lai_thi_dong_bo_gia_cho_chua_ban. Sự kiện đã lệch sẵn: resync-inventory
A8: 4 | B8: Bán trùng ghế: bỏ giữ chỗ chạy chồng lên đặt chỗ — bên đến sau ghi đè trạng thái giữ chỗ vô điều kiện, ghế RESERVED bị trả về kho và bán lần hai (tái hiện bằng ReleaseReserveRaceIT trên PostgreSQL thật) | C8: SeatHoldRepository.updateStatus thành compare-and-set (WHERE status='ACTIVE', trả boolean); ReleaseHoldHandler, ReserveSeatsHandler, ExpireHoldsJob xử lý bên thua
A9: 5 | B9: Lối tắt holdId của PlaceOrderHandler trả đơn của người khác kèm QR và link thanh toán | C9: kiểm chủ đơn, trả 404
A10: 6 | B10: Giảm giá làm tròn dồn vào dòng cuối; dòng cuối là vé 0đ thì vượt đơn giá, OrderItem từ chối, khách nhận "thử lại" mãi | C10: dồn phần dư vào dòng giá cao nhất
A11: 7 | B11: Order.close() nhận PAID/REFUNDED/MANUAL_REVIEW làm lý do — đường vào PAID không qua markPaid, không có paidAt | C11: chỉ EXPIRED / CANCELLED
A12: 8 | B12: limit/offset âm xuống tới SQL → 500 | C12: kẹp ở OrderController, MyTicketsController
A13: 9 | B13: ORG_ADMIN mời email mình kiểm soát làm ORG_OWNER, và hạ / gỡ được ORG_OWNER khác (leo thang đặc quyền) | C13: InviteMemberHandler, ManageMembersHandler
A14: 10 | B14: Đổi vai trò sang SUPER_ADMIN/CUSTOMER lọt qua aggregate rồi nổ CHECK của DB → 500 | C14: Organization.changeRole, handlers → 400
A15: 11 | B15: Hai lệnh sửa thành viên chạy chồng: lệnh sau xoá mất người vừa nhận lời mời / chèn lại người vừa bị gỡ | C15: khoá dòng tổ chức (FOR UPDATE) trong giao dịch ghi (OrganizationConcurrencyIT)
A16: 12 | B16: Huỷ lời mời nhân viên xoá tài khoản Keycloak rồi mới phát hiện tổ chức bị khoá — rollback DB nhưng tài khoản đã mất | C16: kiểm tổ chức trước khi gọi hệ thống ngoài
... A33: 29 | B33: Frontend: csv.ts không chặn công thức bắt đầu bằng TAB/CR (CSV injection); event-report.ts xuất giờ theo múi giờ máy thay vì giờ Việt Nam | C33: sửa trong packages/ui, apps/web-admin

Sheet Khoảng trống
A1: Khoảng trống kiểm thử đã biết
A2: Những gì chưa kiểm được, vì sao, và test cần viết tiếp.
A4: STT | B4: Khoảng trống | C4: Lý do | D4: Test cần viết tiếp
A5: 1 | B5: Mobile (4 app React Native) | C5: Ngoài phạm vi đợt này; có thay đổi chưa commit của người dùng ở apps/mobile-* | D5: Jest + React Native Testing Library; Maestro/Detox cho E2E
A6: 2 | B6: Đăng nhập Keycloak thật, đăng ký, Google IdP | C6: Cần Keycloak + realm thật; E2E dùng nhà phát hành OIDC giả (Authorization Code + PKCE) | D6: E2E nightly với deploy/compose/infra.yml
A7: 3 | B7: Trang thanh toán payOS | C7: payOS không có sandbox (README gốc). Luồng được kiểm bằng FakePayos và simulate-transfer | D7: Không thể tự động hoá an toàn; kiểm tay với tài khoản thật số tiền nhỏ
A8: 4 | B8: Hết hạn / làm mới token giữa phiên | C8: Token giả sống 300 giây | D8: Test với đồng hồ giả + Keycloak thật
A9: 5 | B9: Cập nhật chỗ ngồi realtime ở trình duyệt | C9: Cần realtime-gateway + RabbitMQ trong E2E | D9: E2E có hạ tầng đầy đủ
A10: 6 | B10: Sơ đồ chỗ ngồi vẽ trên trang đặt vé | C10: Fixture cố ý không có floor plan | D10: Thêm fixture floor plan và kiểm chọn ghế bằng chuột
A11: 7 | B11: payOS thật (trang thanh toán, webhook thật) | C11: payOS không có sandbox; checkout.js đã chạy với payOS giả (load-tests/fake-payos), xem load-test-report.md | D11: Kiểm tay một lần với số tiền nhỏ trước khi lên production — không tự động hoá an toàn được
A12: 8 | B12: Đạt 10.000 VU / p95 hold ≤ 300 ms (load-test-plan.md) | C12: Như trên | D12: Gatling/k6 phân tán
A13: 9 | B13: Kill Redis giữa lúc giữ chỗ → 503 retryable, worker khởi động lại → hết hạn bù | C13: Cần phá hạ tầng có chủ đích | D13: IT với Toxiproxy / container dừng giữa chừng
A14: 10 | B14: Webhook payOS đến cùng lúc ExpireOrdersJob đóng đơn | C14: Cuộc đua giữa hai service | D14: IT hai service hoặc test đồng thời ở ordering với hàng giả điều khiển được
A15: 11 | B15: Tải thực tế của JDBC repository (truy vấn thống kê) | C15: Chỉ kiểm đúng/sai qua IT có sẵn | D15: EXPLAIN + dữ liệu lớn
A16: 12 | B16: Tệp tải lên (poster, ảnh sơ đồ) | C16: Đã kiểm content-type, kích thước, đuôi và không phục vụ SVG/HTML; chưa kiểm quét mã độc | D16: Tích hợp ClamAV nếu cần
A17: 13 | B17: Điều kiện @Conditional của OutboxAutoConfiguration, IdempotencyAutoConfiguration | C17: Chỉ là wiring | D17: ApplicationContextRunner

Sheet Hướng dẫn chạy
A1: Lệnh chạy từng bộ test
A2: Chạy từ thư mục được ghi trong cột 'Thư mục'.
A4: Hệ | B4: Thư mục | C4: Lệnh | D4: Ghi chú
A5: Backend | B5: backend/ | C5: ./mvnw -B verify -DskipITs | D5: Unit + API slice + ArchUnit (không cần Docker)
A6: Backend | B6: backend/ | C6: ./mvnw -B -pl services/ordering-service verify -DskipITs | D6: Một service
A7: Backend | B7: backend/ | C7: ./mvnw -B -pl services/ordering-service test -Dtest=PlaceOrderHandlerTest | D7: Một lớp test
A8: Backend | B8: backend/ | C8: ./mvnw -B verify -Dsurefire.skip=true | D8: Chỉ integration (cần Docker Desktop đang chạy)
A9: Backend | B9: backend/ | C9: ./mvnw -B verify | D9: Mọi thứ an toàn cho CI
A10: Backend | B10: backend/ | C10: ./mvnw -B verify -Pcoverage | D10: Thêm JaCoCo; báo cáo gộp ở target/site/jacoco-merged/ mỗi module
A11: Backend | B11: repo gốc | C11: python scripts/coverage-summary.py --classes | D11: Bảng coverage toàn repo + 25 lớp thiếu nhiều dòng nhất
A12: Backend | B12: backend/ | C12: ./mvnw -B spotless:check | D12: Lint (sửa: spotless:apply)
A13: Frontend | B13: frontend/ | C13: corepack pnpm test | D13: Unit mọi gói/app
A14: Frontend | B14: frontend/ | C14: corepack pnpm test:coverage | D14: Coverage
A15: Frontend | B15: frontend/ | C15: corepack pnpm --filter @nexaticket/web-customer test:e2e | D15: E2E Playwright (một next dev, tự dừng khi xong)
... A19: Báo cáo | B19: repo gốc | C19: python scripts/build-test-report.py | D19: Sinh lại workbook này từ kết quả chạy gần nhất
A21: • Yêu cầu: JDK 21 (JAVA_HOME), Docker Desktop đang chạy (cho integration), Node ≥ 20 + corepack, Playwright Chromium (corepack pnpm exec playwright install chromium).
A22: • Không cần biến môi trường cho unit/slice test. E2E tự sinh AUTH_SECRET và dùng nhà phát hành OIDC giả — không đọc .env.local.
A23: • Máy 16 GB: chạy integration tuần tự, MAVEN_OPTS=-Xmx512m; Docker Desktop (WSL) chiếm ~6 GB.

Sheet Danh mục test tự động
A1: Danh mục test tự động — mọi test đã chạy
A2: Nguồn: báo cáo Surefire/Failsafe, Vitest, Playwright của lần chạy gần nhất. Tên = @DisplayName trong mã.
A4: STT | B4: Hệ | C4: Module | D4: Mức | E4: Lớp test | F4: Nhóm | G4: Tên test (hành vi được kiểm) | H4: Phương thức | I4: Kết quả | J4: Thời gian (s)
A5: 1 | B5: Backend | C5: shared-kernel | D5: Unit | E5: RoleMatrixTest | G5: PLATFORM_SUPPORT_HANDLE chỉ SUPER_ADMIN có — ban tổ chức không đọc được chat của khách | H5: support_handle_chi_super_admin | I5: Đạt | J5: 0.17
A6: 2 | B6: Backend | C6: shared-kernel | D6: Unit | E6: RoleMatrixTest | G6: không vai trò tổ chức nào có quyền PLATFORM_* — kể cả chủ sở hữu | H6: khong_ai_ngoai_super_admin_co_quyen_nen_tang(Role)[1] | I6: Đạt | J6: 0.037
A7: 3 | B7: Backend | C7: shared-kernel | D7: Unit | E7: RoleMatrixTest | G7: không vai trò tổ chức nào có quyền PLATFORM_* — kể cả chủ sở hữu | H7: khong_ai_ngoai_super_admin_co_quyen_nen_tang(Role)[2] | I7: Đạt | J7: 0.007
A8: 4 | B8: Backend | C8: shared-kernel | D8: Unit | E8: RoleMatrixTest | G8: không vai trò tổ chức nào có quyền PLATFORM_* — kể cả chủ sở hữu | H8: khong_ai_ngoai_super_admin_co_quyen_nen_tang(Role)[3] | I8: Đạt | J8: 0.006
A9: 5 | B9: Backend | C9: shared-kernel | D9: Unit | E9: RoleMatrixTest | G9: không vai trò tổ chức nào có quyền PLATFORM_* — kể cả chủ sở hữu | H9: khong_ai_ngoai_super_admin_co_quyen_nen_tang(Role)[4] | I9: Đạt | J9: 0.003
A10: 6 | B10: Backend | C10: shared-kernel | D10: Unit | E10: RoleMatrixTest | G10: không vai trò tổ chức nào có quyền PLATFORM_* — kể cả chủ sở hữu | H10: khong_ai_ngoai_super_admin_co_quyen_nen_tang(Role)[5] | I10: Đạt | J10: 0.003
A11: 7 | B11: Backend | C11: shared-kernel | D11: Unit | E11: RoleMatrixTest | G11: SUPER_ADMIN: đúng sáu quyền nền tảng, không có quyền tổ chức nào | H11: super_admin | I11: Đạt | J11: 0.002
A12: 8 | B12: Backend | C12: shared-kernel | D12: Unit | E12: RoleMatrixTest | G12: PLATFORM_FINANCE_VIEW chỉ SUPER_ADMIN có — tổ chức không thấy sổ cái (ADR-1010) | H12: finance_chi_super_admin | I12: Đạt | J12: 0.003
A13: 9 | B13: Backend | C13: shared-kernel | D13: Unit | E13: RoleMatrixTest | G13: isOrganizationScoped: SUPER_ADMIN và CUSTOMER không gắn tổ chức, bốn vai trò còn lại có | H13: pham_vi_to_chuc | I13: Đạt | J13: 0.009
A14: 10 | B14: Backend | C14: shared-kernel | D14: Unit | E14: RoleMatrixTest | G14: CHECKIN_STAFF chỉ quét vé; CUSTOMER không có quyền nào | H14: staff_va_customer | I14: Đạt | J14: 0.005
A15: 11 | B15: Backend | C15: shared-kernel | D15: Unit | E15: RoleMatrixTest | G15: mỗi quyền được gán cho ít nhất một vai trò — không có quyền mồ côi | H15: khong_co_quyen_mo_coi(Permission)[1] | I15: Đạt | J15: 0.005
A16: 12 | B16: Backend | C16: shared-kernel | D16: Unit | E16: RoleMatrixTest | G16: mỗi quyền được gán cho ít nhất một vai trò — không có quyền mồ côi | H16: khong_co_quyen_mo_coi(Permission)[2] | I16: Đạt | J16: 0.002
... A48: 44 | B48: Backend | C48: shared-kernel | D48: Unit | E48: RoleMatrixTest | G48: tập quyền không sửa được từ bên ngoài | H48: tap_quyen_bat_bien | I48: Đạt | J48: 0.019
A49: 45 | B49: Backend | C49: shared-kernel | D49: Unit | E49: IdentifiersTest › Context | F49: CorrelationContext | G49: chưa set: current() là 'unknown', không bao giờ null | H49: mac_dinh_unknown | I49: Đạt | J49: 0.032
A50: 46 | B50: Backend | C50: shared-kernel | D50: Unit | E50: IdentifiersTest › Context | F50: CorrelationContext | G50: currentOrGenerate: sinh và GIỮ lại mã nếu chưa có; có rồi thì giữ nguyên | H50: current_or_generate | I50: Đạt | J50: 0.272
A51: 47 | B51: Backend | C51: shared-kernel | D51: Unit | E51: IdentifiersTest › Context | F51: CorrelationContext | G51: ngữ cảnh theo từng luồng: luồng khác không thấy mã của luồng này | H51: theo_tung_luong | I51: Đạt | J51: 0.02
A52: 48 | B52: Backend | C52: shared-kernel | D52: Unit | E52: IdentifiersTest › Context | F52: CorrelationContext | G52: set rồi current() trả đúng; clear() về unknown | H52: set_clear | I52: Đạt | J52: 0.006
A53: 49 | B53: Backend | C53: shared-kernel | D53: Unit | E53: IdentifiersTest › Correlation | F53: CorrelationId | G53: toString là chính giá trị | H53: to_string | I53: Đạt | J53: 0.002
A54: 50 | B54: Backend | C54: shared-kernel | D54: Unit | E54: IdentifiersTest › Correlation | F54: CorrelationId | G54: generate: 26 ký tự Crockford Base32 (không I, L, O, U), hoa | H54: generate_dung_khuon | I54: Đạt | J54: 0.086
A55: 51 | B55: Backend | C55: shared-kernel | D55: Unit | E55: IdentifiersTest › Correlation | F55: CorrelationId | G55: generate: không trùng trong 10.000 lần sinh | H55: generate_khong_trung | I55: Đạt | J55: 0.288
A56: 52 | B56: Backend | C56: shared-kernel | D56: Unit | E56: IdentifiersTest › Correlation | F56: CorrelationId | G56: giá trị hợp lệ: 1 tới 64 ký tự; rỗng, trắng, 65 ký tự, null bị từ chối | H56: rang_buoc_do_dai | I56: Đạt | J56: 0.01
A57: 53 | B57: Backend | C57: shared-kernel | D57: Unit | E57: IdentifiersTest › Correlation | F57: CorrelationId | G57: 10 ký tự đầu mã hoá thời gian nên sắp xếp được theo thứ tự sinh | H57: sap_xep_theo_thoi_gian | I57: Đạt | J57: 0.017
A58: 54 | B58: Backend | C58: shared-kernel | D58: Unit | E58: IdentifiersTest › Ids | F58: TenantId / UserId | G58: dùng được làm khoá map/set | H58: khoa_map | I58: Đạt | J58: 0.045
A59: 55 | B59: Backend | C59: shared-kernel | D59: Unit | E59: IdentifiersTest › Ids | F59: TenantId / UserId | G59: hai kiểu id không bao giờ bằng nhau dù cùng UUID — nhầm thứ tự tham số không lọt | H59: khac_kieu_khong_bang_nhau | I59: Đạt | J59: 0.008
A60: 56 | B60: Backend | C60: shared-kernel | D60: Unit | E60: IdentifiersTest › Ids | F60: TenantId / UserId | G60: parse và of cho cùng một giá trị; toString là chuỗi UUID | H60: parse_of_tostring | I60: Đạt | J60: 0.007
... A90: 86 | B90: Backend | C90: shared-kernel | D90: Unit | E90: MoneyEdgeCaseTest › PercentOf | F90: percentOf (basis point, làm tròn xuống) | G90: hoa hồng + phần còn lại luôn bằng đúng tổng — không rơi mất một đồng | H90: khong_mat_dong_nao | I90: Đạt | J90: 0.004
A91: 87 | B91: Backend | C91: shared-kernel | D91: Unit | E91: MoneyTest | G91: khong cho so am | H91: khong_cho_so_am | I91: Đạt | J91: 0.002
A92: 88 | B92: Backend | C92: shared-kernel | D92: Unit | E92: MoneyTest | G92: tru qua so du bi chan | H92: tru_qua_so_du_bi_chan | I92: Đạt | J92: 0.005
A93: 89 | B93: Backend | C93: shared-kernel | D93: Unit | E93: MoneyTest | G93: hoa hong 5 phan tram lam tron xuong | H93: hoa_hong_5_phan_tram_lam_tron_xuong | I93: Đạt | J93: 0.001
A94: 90 | B94: Backend | C94: shared-kernel | D94: Unit | E94: MoneyTest | G94: format theo kieu viet nam | H94: format_theo_kieu_viet_nam | I94: Đạt | J94: 0.001
A95: 91 | B95: Backend | C95: shared-kernel | D95: Unit | E95: MoneyTest | G95: tran so nem exception thay vi cho ket qua sai | H95: tran_so_nem_exception_thay_vi_cho_ket_qua_sai | I95: Đạt | J95: 0.001
A96: 92 | B96: Backend | C96: shared-kernel | D96: Unit | E96: TimeWindowEdgeCaseTest | G96: duration bằng end - start | H96: duration | I96: Đạt | J96: 0.003
A97: 93 | B97: Backend | C97: shared-kernel | D97: Unit | E97: TimeWindowEdgeCaseTest | G97: đệm âm thu hẹp khoảng; thu hẹp quá mức thì bị từ chối thay vì tạo khoảng ngược | H97: dem_am | I97: Đạt | J97: 0.008
A98: 94 | B98: Backend | C98: shared-kernel | D98: Unit | E98: TimeWindowEdgeCaseTest | G98: contains: gồm start, loại end, loại điểm ngoài | H98: contains | I98: Đạt | J98: 0.001
A99: 95 | B99: Backend | C99: shared-kernel | D99: Unit | E99: TimeWindowEdgeCaseTest | G99: expandedBy nới đúng hai đầu; đệm 0 giữ nguyên; bản gốc bất biến | H99: expanded_by | I99: Đạt | J99: 0.008
A100: 96 | B100: Backend | C100: shared-kernel | D100: Unit | E100: TimeWindowEdgeCaseTest | G100: giao nhau đối xứng, lồng nhau và trùng hệt đều là giao | H100: giao_nhau | I100: Đạt | J100: 0.002
A101: 97 | B101: Backend | C101: shared-kernel | D101: Unit | E101: TimeWindowEdgeCaseTest | G101: hai khoảng liền kề (end = start kia) không giao nhau — hai suất nối tiếp không bị báo trùng | H101: lien_ke_khong_giao | I101: Đạt | J101: 0.002
...
