Workbook

Sheet Tổng quan
B2: KẾ HOẠCH DỰ ÁN NEXATICKET — NỀN TẢNG BÁN VÉ SỰ KIỆN
B4: Ngày bắt đầu | C4: 46239 | D4: ← ô nhập (nền vàng). Mọi ngày trong file tính từ ô này.
B5: Số tuần | C5: 14
B6: Ngày kết thúc | C6: =C4+7*C5-1
B7: Nhịp báo cáo | C7: 2–3 tuần / lần
B9: THÀNH VIÊN
B10: Thành viên | C10: Họ tên đầy đủ | D10: Mảng phụ trách | E10: Số việc / Đã xong
B11: Thiện | D11: Backend, cơ sở dữ liệu, AI, kiểm thử, hạ tầng/deploy | E11: =COUNTIF('Kế hoạch'!$E:$E,"Thiện")&" việc / "&COUNTIFS('Kế hoạch'!$E:$E,"Thiện",'Kế hoạch'!$K:$K,"Hoàn thành")&" xong"
B12: Hạnh | D12: Mobile, frontend web, báo cáo (slide, quyển báo cáo) | E12: =COUNTIF('Kế hoạch'!$E:$E,"Hạnh")&" việc / "&COUNTIFS('Kế hoạch'!$E:$E,"Hạnh",'Kế hoạch'!$K:$K,"Hoàn thành")&" xong"
B15: LỊCH BÁO CÁO
B16: Lần · Tuần | C16: Ngày báo cáo | D16: Nội dung | E16: Người trình bày
B17: Lần 1 · Tuần 3 | C17: ='Báo cáo'!C4 | D17: Timeline dự án, kiến trúc dự án; thầy hướng dẫn phần AI cần làm | E17: Thiện (kiến trúc, AI) · Hạnh (timeline, slide)
B18: Lần 2 · Tuần 6 | C18: ='Báo cáo'!C5 | D18: Sườn cơ bản của dự án | E18: Thiện (backend) · Hạnh (frontend)
B19: Lần 3 · Tuần 9 | C19: ='Báo cáo'!C6 | D19: AI chatbox hỗ trợ người dùng; sửa giao diện admin dashboard | E19: Thiện (AI chatbox) · Hạnh (admin dashboard)
B20: Lần 4 · Tuần 12 | C20: ='Báo cáo'!C7 | D20: Demo mobile app; xuất file xlsx | E20: Hạnh (mobile) · Thiện (API, xuất xlsx)
B21: Lần 5 · Tuần 15 (đề xuất) | C21: ='Báo cáo'!C8 | D21: Tổng kết, nghiệm thu, chuẩn bị bảo vệ | E21: Cả hai
B23: Cách dùng file
B24: • Ô nền vàng chữ xanh là ô nhập; ô chữ đen là công thức; chữ xanh lá lấy từ sheet khác.
B25: • Sheet 'Kế hoạch': đổi cột Trạng thái (danh sách chọn) để cập nhật tiến độ; biểu đồ Gantt và bảng phân công tự đổi theo.
B26: • Cột 'Bằng chứng trong repo' ghi đường dẫn tới code/tài liệu đã có trong F:\kltnnnn, để đối chiếu khi báo cáo.
B27: • Lần 1–4 theo yêu cầu của nhóm. Lần 5 là đề xuất (tổng kết) để khép 13–14 tuần; xoá nếu không cần.
B28: • Trạng thái được đánh giá theo hiện trạng repo ngày 22/10/2026.

Sheet Kế hoạch
A1: KẾ HOẠCH CHI TIẾT & BIỂU ĐỒ GANTT
A2: Màu thanh: xanh dương = Thiện · cam = Hạnh · xanh lá = Cả hai. Cột tuần viền đỏ = tuần có buổi báo cáo.
M3: ="T"&1 | N3: ="T"&2 | O3: ="BC"&1 | P3: ="T"&4 | Q3: ="T"&5 | R3: ="BC"&2 | S3: ="T"&7 | T3: ="T"&8 | U3: ="BC"&3 | V3: ="T"&10 | W3: ="T"&11 | X3: ="BC"&4 | Y3: ="T"&13 | Z3: ="T"&14
A4: ID | B4: Đợt | C4: Hạng mục | D4: Công việc | E4: Phụ trách | F4: Tuần BĐ | G4: Số tuần | H4: Ngày bắt đầu | I4: Ngày kết thúc | J4: Sản phẩm bàn giao | K4: Trạng thái | L4: Bằng chứng trong repo | M4: ='Tổng quan'!$C$4+7*(1-1) | N4: ='Tổng quan'!$C$4+7*(2-1) | O4: ='Tổng quan'!$C$4+7*(3-1) | P4: ='Tổng quan'!$C$4+7*(4-1) | Q4: ='Tổng quan'!$C$4+7*(5-1) | R4: ='Tổng quan'!$C$4+7*(6-1) | S4: ='Tổng quan'!$C$4+7*(7-1) | T4: ='Tổng quan'!$C$4+7*(8-1) | U4: ='Tổng quan'!$C$4+7*(9-1) | V4: ='Tổng quan'!$C$4+7*(10-1) | W4: ='Tổng quan'!$C$4+7*(11-1) | X4: ='Tổng quan'!$C$4+7*(12-1) | Y4: ='Tổng quan'!$C$4+7*(13-1) | Z4: ='Tổng quan'!$C$4+7*(14-1)
A5: Đợt 1 · Khởi động & kiến trúc
A6: 1.1 | B6: 1 | C6: Phân tích | D6: Khảo sát nghiệp vụ bán vé, đối thủ (Ticketbox), chốt phạm vi MVP | E6: Cả hai | F6: 1 | G6: 1 | H6: ='Tổng quan'!$C$4+7*(F6-1) | I6: =H6+7*G6-1 | J6: Danh sách tính năng MVP, quyết định sản phẩm | K6: Hoàn thành | L6: docs/00-discovery/product-decisions.md | M6: =IF(AND(1>=$F6,1<$F6+$G6),1,"") | N6: =IF(AND(2>=$F6,2<$F6+$G6),1,"") | O6: =IF(AND(3>=$F6,3<$F6+$G6),1,"") | P6: =IF(AND(4>=$F6,4<$F6+$G6),1,"") | Q6: =IF(AND(5>=$F6,5<$F6+$G6),1,"") | R6: =IF(AND(6>=$F6,6<$F6+$G6),1,"") | S6: =IF(AND(7>=$F6,7<$F6+$G6),1,"") | T6: =IF(AND(8>=$F6,8<$F6+$G6),1,"") | U6: =IF(AND(9>=$F6,9<$F6+$G6),1,"") | V6: =IF(AND(10>=$F6,10<$F6+$G6),1,"") | W6: =IF(AND(11>=$F6,11<$F6+$G6),1,"") | X6: =IF(AND(12>=$F6,12<$F6+$G6),1,"") | Y6: =IF(AND(13>=$F6,13<$F6+$G6),1,"") | Z6: =IF(AND(14>=$F6,14<$F6+$G6),1,"")
A7: 1.2 | B7: 1 | C7: Phân tích | D7: Đặc tả yêu cầu (SRS), ma trận phân quyền RBAC, chỉ số thành công | E7: Thiện | F7: 1 | G7: 2 | H7: ='Tổng quan'!$C$4+7*(F7-1) | I7: =H7+7*G7-1 | J7: SRS, RBAC, success-metrics | K7: Hoàn thành | L7: docs/00-discovery/srs.md, rbac-permission-matrix.md | M7: =IF(AND(1>=$F7,1<$F7+$G7),1,"") | N7: =IF(AND(2>=$F7,2<$F7+$G7),1,"") | O7: =IF(AND(3>=$F7,3<$F7+$G7),1,"") | P7: =IF(AND(4>=$F7,4<$F7+$G7),1,"") | Q7: =IF(AND(5>=$F7,5<$F7+$G7),1,"") | R7: =IF(AND(6>=$F7,6<$F7+$G7),1,"") | S7: =IF(AND(7>=$F7,7<$F7+$G7),1,"") | T7: =IF(AND(8>=$F7,8<$F7+$G7),1,"") | U7: =IF(AND(9>=$F7,9<$F7+$G7),1,"") | V7: =IF(AND(10>=$F7,10<$F7+$G7),1,"") | W7: =IF(AND(11>=$F7,11<$F7+$G7),1,"") | X7: =IF(AND(12>=$F7,12<$F7+$G7),1,"") | Y7: =IF(AND(13>=$F7,13<$F7+$G7),1,"") | Z7: =IF(AND(14>=$F7,14<$F7+$G7),1,"")
A8: 1.3 | B8: 1 | C8: Kiến trúc | D8: Thiết kế kiến trúc microservices + DDD, chia bounded context, viết ADR | E8: Thiện | F8: 1 | G8: 2 | H8: ='Tổng quan'!$C$4+7*(F8-1) | I8: =H8+7*G8-1 | J8: Sơ đồ kiến trúc, ADR-1001… | K8: Hoàn thành | L8: docs/architecture-v2/ | M8: =IF(AND(1>=$F8,1<$F8+$G8),1,"") | N8: =IF(AND(2>=$F8,2<$F8+$G8),1,"") | O8: =IF(AND(3>=$F8,3<$F8+$G8),1,"") | P8: =IF(AND(4>=$F8,4<$F8+$G8),1,"") | Q8: =IF(AND(5>=$F8,5<$F8+$G8),1,"") | R8: =IF(AND(6>=$F8,6<$F8+$G8),1,"") | S8: =IF(AND(7>=$F8,7<$F8+$G8),1,"") | T8: =IF(AND(8>=$F8,8<$F8+$G8),1,"") | U8: =IF(AND(9>=$F8,9<$F8+$G8),1,"") | V8: =IF(AND(10>=$F8,10<$F8+$G8),1,"") | W8: =IF(AND(11>=$F8,11<$F8+$G8),1,"") | X8: =IF(AND(12>=$F8,12<$F8+$G8),1,"") | Y8: =IF(AND(13>=$F8,13<$F8+$G8),1,"") | Z8: =IF(AND(14>=$F8,14<$F8+$G8),1,"")
A9: 1.4 | B9: 1 | C9: CSDL | D9: Thiết kế CSDL theo service: ghế, đơn hàng, vé, sổ cái | E9: Thiện | F9: 2 | G9: 1 | H9: ='Tổng quan'!$C$4+7*(F9-1) | I9: =H9+7*G9-1 | J9: ERD, data model | K9: Hoàn thành | L9: docs/architecture-v2/, docs/03-seat-checkout/ | M9: =IF(AND(1>=$F9,1<$F9+$G9),1,"") | N9: =IF(AND(2>=$F9,2<$F9+$G9),1,"") | O9: =IF(AND(3>=$F9,3<$F9+$G9),1,"") | P9: =IF(AND(4>=$F9,4<$F9+$G9),1,"") | Q9: =IF(AND(5>=$F9,5<$F9+$G9),1,"") | R9: =IF(AND(6>=$F9,6<$F9+$G9),1,"") | S9: =IF(AND(7>=$F9,7<$F9+$G9),1,"") | T9: =IF(AND(8>=$F9,8<$F9+$G9),1,"") | U9: =IF(AND(9>=$F9,9<$F9+$G9),1,"") | V9: =IF(AND(10>=$F9,10<$F9+$G9),1,"") | W9: =IF(AND(11>=$F9,11<$F9+$G9),1,"") | X9: =IF(AND(12>=$F9,12<$F9+$G9),1,"") | Y9: =IF(AND(13>=$F9,13<$F9+$G9),1,"") | Z9: =IF(AND(14>=$F9,14<$F9+$G9),1,"")
A10: 1.5 | B10: 1 | C10: AI | D10: Đề xuất hướng AI (chatbot RAG hỗ trợ khách) để xin ý kiến thầy | E10: Thiện | F10: 2 | G10: 1 | H10: ='Tổng quan'!$C$4+7*(F10-1) | I10: =H10+7*G10-1 | J10: Bản đề xuất AI 1 trang | K10: Hoàn thành | L10: docs/05-ai-scale/ | M10: =IF(AND(1>=$F10,1<$F10+$G10),1,"") | N10: =IF(AND(2>=$F10,2<$F10+$G10),1,"") | O10: =IF(AND(3>=$F10,3<$F10+$G10),1,"") | P10: =IF(AND(4>=$F10,4<$F10+$G10),1,"") | Q10: =IF(AND(5>=$F10,5<$F10+$G10),1,"") | R10: =IF(AND(6>=$F10,6<$F10+$G10),1,"") | S10: =IF(AND(7>=$F10,7<$F10+$G10),1,"") | T10: =IF(AND(8>=$F10,8<$F10+$G10),1,"") | U10: =IF(AND(9>=$F10,9<$F10+$G10),1,"") | V10: =IF(AND(10>=$F10,10<$F10+$G10),1,"") | W10: =IF(AND(11>=$F10,11<$F10+$G10),1,"") | X10: =IF(AND(12>=$F10,12<$F10+$G10),1,"") | Y10: =IF(AND(13>=$F10,13<$F10+$G10),1,"") | Z10: =IF(AND(14>=$F10,14<$F10+$G10),1,"")
A11: 1.6 | B11: 1 | C11: Giao diện | D11: Wireframe và luồng màn hình web + mobile | E11: Hạnh | F11: 1 | G11: 2 | H11: ='Tổng quan'!$C$4+7*(F11-1) | I11: =H11+7*G11-1 | J11: Wireframe, IA | K11: Hoàn thành | L11: docs/ui/, docs/ui/mobile/ | M11: =IF(AND(1>=$F11,1<$F11+$G11),1,"") | N11: =IF(AND(2>=$F11,2<$F11+$G11),1,"") | O11: =IF(AND(3>=$F11,3<$F11+$G11),1,"") | P11: =IF(AND(4>=$F11,4<$F11+$G11),1,"") | Q11: =IF(AND(5>=$F11,5<$F11+$G11),1,"") | R11: =IF(AND(6>=$F11,6<$F11+$G11),1,"") | S11: =IF(AND(7>=$F11,7<$F11+$G11),1,"") | T11: =IF(AND(8>=$F11,8<$F11+$G11),1,"") | U11: =IF(AND(9>=$F11,9<$F11+$G11),1,"") | V11: =IF(AND(10>=$F11,10<$F11+$G11),1,"") | W11: =IF(AND(11>=$F11,11<$F11+$G11),1,"") | X11: =IF(AND(12>=$F11,12<$F11+$G11),1,"") | Y11: =IF(AND(13>=$F11,13<$F11+$G11),1,"") | Z11: =IF(AND(14>=$F11,14<$F11+$G11),1,"")
A12: 1.7 | B12: 1 | C12: Báo cáo | D12: Lập timeline, slide và biên bản báo cáo lần 1 | E12: Hạnh | F12: 2 | G12: 1 | H12: ='Tổng quan'!$C$4+7*(F12-1) | I12: =H12+7*G12-1 | J12: Slide lần 1, file kế hoạch | K12: Hoàn thành | L12: docs/DELIVERY-PLAN-3M.md | M12: =IF(AND(1>=$F12,1<$F12+$G12),1,"") | N12: =IF(AND(2>=$F12,2<$F12+$G12),1,"") | O12: =IF(AND(3>=$F12,3<$F12+$G12),1,"") | P12: =IF(AND(4>=$F12,4<$F12+$G12),1,"") | Q12: =IF(AND(5>=$F12,5<$F12+$G12),1,"") | R12: =IF(AND(6>=$F12,6<$F12+$G12),1,"") | S12: =IF(AND(7>=$F12,7<$F12+$G12),1,"") | T12: =IF(AND(8>=$F12,8<$F12+$G12),1,"") | U12: =IF(AND(9>=$F12,9<$F12+$G12),1,"") | V12: =IF(AND(10>=$F12,10<$F12+$G12),1,"") | W12: =IF(AND(11>=$F12,11<$F12+$G12),1,"") | X12: =IF(AND(12>=$F12,12<$F12+$G12),1,"") | Y12: =IF(AND(13>=$F12,13<$F12+$G12),1,"") | Z12: =IF(AND(14>=$F12,14<$F12+$G12),1,"")
A13: Đợt 2 · Sườn cơ bản
A14: 2.1 | B14: 2 | C14: Backend | D14: Khung monorepo backend, thư viện dùng chung (web, security, outbox, idempotency), ArchUnit | E14: Thiện | F14: 3 | G14: 1 | H14: ='Tổng quan'!$C$4+7*(F14-1) | I14: =H14+7*G14-1 | J14: backend/platform/* | K14: Hoàn thành | L14: backend/platform/ | M14: =IF(AND(1>=$F14,1<$F14+$G14),1,"") | N14: =IF(AND(2>=$F14,2<$F14+$G14),1,"") | O14: =IF(AND(3>=$F14,3<$F14+$G14),1,"") | P14: =IF(AND(4>=$F14,4<$F14+$G14),1,"") | Q14: =IF(AND(5>=$F14,5<$F14+$G14),1,"") | R14: =IF(AND(6>=$F14,6<$F14+$G14),1,"") | S14: =IF(AND(7>=$F14,7<$F14+$G14),1,"") | T14: =IF(AND(8>=$F14,8<$F14+$G14),1,"") | U14: =IF(AND(9>=$F14,9<$F14+$G14),1,"") | V14: =IF(AND(10>=$F14,10<$F14+$G14),1,"") | W14: =IF(AND(11>=$F14,11<$F14+$G14),1,"") | X14: =IF(AND(12>=$F14,12<$F14+$G14),1,"") | Y14: =IF(AND(13>=$F14,13<$F14+$G14),1,"") | Z14: =IF(AND(14>=$F14,14<$F14+$G14),1,"")
A15: 2.2 | B15: 2 | C15: Hạ tầng | D15: Docker Compose local (PostgreSQL, Redis, RabbitMQ, Keycloak), CI GitHub Actions | E15: Thiện | F15: 3 | G15: 1 | H15: ='Tổng quan'!$C$4+7*(F15-1) | I15: =H15+7*G15-1 | J15: deploy/compose/infra.yml, .github/workflows/backend.yml | K15: Hoàn thành | L15: deploy/compose/, .github/workflows/ | M15: =IF(AND(1>=$F15,1<$F15+$G15),1,"") | N15: =IF(AND(2>=$F15,2<$F15+$G15),1,"") | O15: =IF(AND(3>=$F15,3<$F15+$G15),1,"") | P15: =IF(AND(4>=$F15,4<$F15+$G15),1,"") | Q15: =IF(AND(5>=$F15,5<$F15+$G15),1,"") | R15: =IF(AND(6>=$F15,6<$F15+$G15),1,"") | S15: =IF(AND(7>=$F15,7<$F15+$G15),1,"") | T15: =IF(AND(8>=$F15,8<$F15+$G15),1,"") | U15: =IF(AND(9>=$F15,9<$F15+$G15),1,"") | V15: =IF(AND(10>=$F15,10<$F15+$G15),1,"") | W15: =IF(AND(11>=$F15,11<$F15+$G15),1,"") | X15: =IF(AND(12>=$F15,12<$F15+$G15),1,"") | Y15: =IF(AND(13>=$F15,13<$F15+$G15),1,"") | Z15: =IF(AND(14>=$F15,14<$F15+$G15),1,"")
A16: 2.3 | B16: 2 | C16: Backend | D16: identity-service: tổ chức, thành viên, lời mời; đăng nhập OIDC Keycloak; api-gateway | E16: Thiện | F16: 3 | G16: 2 | H16: ='Tổng quan'!$C$4+7*(F16-1) | I16: =H16+7*G16-1 | J16: API identity, gateway | K16: Hoàn thành | L16: backend/services/identity-service, api-gateway | M16: =IF(AND(1>=$F16,1<$F16+$G16),1,"") | N16: =IF(AND(2>=$F16,2<$F16+$G16),1,"") | O16: =IF(AND(3>=$F16,3<$F16+$G16),1,"") | P16: =IF(AND(4>=$F16,4<$F16+$G16),1,"") | Q16: =IF(AND(5>=$F16,5<$F16+$G16),1,"") | R16: =IF(AND(6>=$F16,6<$F16+$G16),1,"") | S16: =IF(AND(7>=$F16,7<$F16+$G16),1,"") | T16: =IF(AND(8>=$F16,8<$F16+$G16),1,"") | U16: =IF(AND(9>=$F16,9<$F16+$G16),1,"") | V16: =IF(AND(10>=$F16,10<$F16+$G16),1,"") | W16: =IF(AND(11>=$F16,11<$F16+$G16),1,"") | X16: =IF(AND(12>=$F16,12<$F16+$G16),1,"") | Y16: =IF(AND(13>=$F16,13<$F16+$G16),1,"") | Z16: =IF(AND(14>=$F16,14<$F16+$G16),1,"")
A17: 2.4 | B17: 2 | C17: Backend | D17: catalog-service: địa điểm, sự kiện, suất diễn, khu, hạng vé, đăng/gỡ sự kiện | E17: Thiện | F17: 4 | G17: 2 | H17: ='Tổng quan'!$C$4+7*(F17-1) | I17: =H17+7*G17-1 | J17: API catalog | K17: Hoàn thành | L17: backend/services/catalog-service | M17: =IF(AND(1>=$F17,1<$F17+$G17),1,"") | N17: =IF(AND(2>=$F17,2<$F17+$G17),1,"") | O17: =IF(AND(3>=$F17,3<$F17+$G17),1,"") | P17: =IF(AND(4>=$F17,4<$F17+$G17),1,"") | Q17: =IF(AND(5>=$F17,5<$F17+$G17),1,"") | R17: =IF(AND(6>=$F17,6<$F17+$G17),1,"") | S17: =IF(AND(7>=$F17,7<$F17+$G17),1,"") | T17: =IF(AND(8>=$F17,8<$F17+$G17),1,"") | U17: =IF(AND(9>=$F17,9<$F17+$G17),1,"") | V17: =IF(AND(10>=$F17,10<$F17+$G17),1,"") | W17: =IF(AND(11>=$F17,11<$F17+$G17),1,"") | X17: =IF(AND(12>=$F17,12<$F17+$G17),1,"") | Y17: =IF(AND(13>=$F17,13<$F17+$G17),1,"") | Z17: =IF(AND(14>=$F17,14<$F17+$G17),1,"")
A18: 2.5 | B18: 2 | C18: Backend | D18: inventory-service: giữ ghế bằng Redis Lua + chặn trùng ở PostgreSQL | E18: Thiện | F18: 4 | G18: 2 | H18: ='Tổng quan'!$C$4+7*(F18-1) | I18: =H18+7*G18-1 | J18: API giữ ghế | K18: Hoàn thành | L18: backend/services/inventory-service | M18: =IF(AND(1>=$F18,1<$F18+$G18),1,"") | N18: =IF(AND(2>=$F18,2<$F18+$G18),1,"") | O18: =IF(AND(3>=$F18,3<$F18+$G18),1,"") | P18: =IF(AND(4>=$F18,4<$F18+$G18),1,"") | Q18: =IF(AND(5>=$F18,5<$F18+$G18),1,"") | R18: =IF(AND(6>=$F18,6<$F18+$G18),1,"") | S18: =IF(AND(7>=$F18,7<$F18+$G18),1,"") | T18: =IF(AND(8>=$F18,8<$F18+$G18),1,"") | U18: =IF(AND(9>=$F18,9<$F18+$G18),1,"") | V18: =IF(AND(10>=$F18,10<$F18+$G18),1,"") | W18: =IF(AND(11>=$F18,11<$F18+$G18),1,"") | X18: =IF(AND(12>=$F18,12<$F18+$G18),1,"") | Y18: =IF(AND(13>=$F18,13<$F18+$G18),1,"") | Z18: =IF(AND(14>=$F18,14<$F18+$G18),1,"")
A19: 2.6 | B19: 2 | C19: Kiểm thử | D19: Test tích hợp Testcontainers: chống bán trùng ghế, cách ly tenant | E19: Thiện | F19: 5 | G19: 1 | H19: ='Tổng quan'!$C$4+7*(F19-1) | I19: =H19+7*G19-1 | J19: SeatHoldConcurrencyIT, OversellBackstopIT | K19: Hoàn thành | L19: backend/services/inventory-service/src/test | M19: =IF(AND(1>=$F19,1<$F19+$G19),1,"") | N19: =IF(AND(2>=$F19,2<$F19+$G19),1,"") | O19: =IF(AND(3>=$F19,3<$F19+$G19),1,"") | P19: =IF(AND(4>=$F19,4<$F19+$G19),1,"") | Q19: =IF(AND(5>=$F19,5<$F19+$G19),1,"") | R19: =IF(AND(6>=$F19,6<$F19+$G19),1,"") | S19: =IF(AND(7>=$F19,7<$F19+$G19),1,"") | T19: =IF(AND(8>=$F19,8<$F19+$G19),1,"") | U19: =IF(AND(9>=$F19,9<$F19+$G19),1,"") | V19: =IF(AND(10>=$F19,10<$F19+$G19),1,"") | W19: =IF(AND(11>=$F19,11<$F19+$G19),1,"") | X19: =IF(AND(12>=$F19,12<$F19+$G19),1,"") | Y19: =IF(AND(13>=$F19,13<$F19+$G19),1,"") | Z19: =IF(AND(14>=$F19,14<$F19+$G19),1,"")
A20: 2.7 | B20: 2 | C20: Frontend | D20: Monorepo frontend (pnpm, turbo), gói ui, tokens, auth, ts-sdk | E20: Hạnh | F20: 3 | G20: 1 | H20: ='Tổng quan'!$C$4+7*(F20-1) | I20: =H20+7*G20-1 | J20: frontend/packages/* | K20: Hoàn thành | L20: frontend/packages/ | M20: =IF(AND(1>=$F20,1<$F20+$G20),1,"") | N20: =IF(AND(2>=$F20,2<$F20+$G20),1,"") | O20: =IF(AND(3>=$F20,3<$F20+$G20),1,"") | P20: =IF(AND(4>=$F20,4<$F20+$G20),1,"") | Q20: =IF(AND(5>=$F20,5<$F20+$G20),1,"") | R20: =IF(AND(6>=$F20,6<$F20+$G20),1,"") | S20: =IF(AND(7>=$F20,7<$F20+$G20),1,"") | T20: =IF(AND(8>=$F20,8<$F20+$G20),1,"") | U20: =IF(AND(9>=$F20,9<$F20+$G20),1,"") | V20: =IF(AND(10>=$F20,10<$F20+$G20),1,"") | W20: =IF(AND(11>=$F20,11<$F20+$G20),1,"") | X20: =IF(AND(12>=$F20,12<$F20+$G20),1,"") | Y20: =IF(AND(13>=$F20,13<$F20+$G20),1,"") | Z20: =IF(AND(14>=$F20,14<$F20+$G20),1,"")
A21: 2.8 | B21: 2 | C21: Frontend | D21: Web khách hàng: trang chủ, danh sách, chi tiết sự kiện, đăng nhập | E21: Hạnh | F21: 4 | G21: 2 | H21: ='Tổng quan'!$C$4+7*(F21-1) | I21: =H21+7*G21-1 | J21: frontend/apps/web-customer | K21: Hoàn thành | L21: frontend/apps/web-customer | M21: =IF(AND(1>=$F21,1<$F21+$G21),1,"") | N21: =IF(AND(2>=$F21,2<$F21+$G21),1,"") | O21: =IF(AND(3>=$F21,3<$F21+$G21),1,"") | P21: =IF(AND(4>=$F21,4<$F21+$G21),1,"") | Q21: =IF(AND(5>=$F21,5<$F21+$G21),1,"") | R21: =IF(AND(6>=$F21,6<$F21+$G21),1,"") | S21: =IF(AND(7>=$F21,7<$F21+$G21),1,"") | T21: =IF(AND(8>=$F21,8<$F21+$G21),1,"") | U21: =IF(AND(9>=$F21,9<$F21+$G21),1,"") | V21: =IF(AND(10>=$F21,10<$F21+$G21),1,"") | W21: =IF(AND(11>=$F21,11<$F21+$G21),1,"") | X21: =IF(AND(12>=$F21,12<$F21+$G21),1,"") | Y21: =IF(AND(13>=$F21,13<$F21+$G21),1,"") | Z21: =IF(AND(14>=$F21,14<$F21+$G21),1,"")
A22: 2.9 | B22: 2 | C22: Frontend | D22: Web quản trị: khung dashboard, tạo địa điểm và sự kiện | E22: Hạnh | F22: 4 | G22: 2 | H22: ='Tổng quan'!$C$4+7*(F22-1) | I22: =H22+7*G22-1 | J22: frontend/apps/web-admin | K22: Hoàn thành | L22: frontend/apps/web-admin | M22: =IF(AND(1>=$F22,1<$F22+$G22),1,"") | N22: =IF(AND(2>=$F22,2<$F22+$G22),1,"") | O22: =IF(AND(3>=$F22,3<$F22+$G22),1,"") | P22: =IF(AND(4>=$F22,4<$F22+$G22),1,"") | Q22: =IF(AND(5>=$F22,5<$F22+$G22),1,"") | R22: =IF(AND(6>=$F22,6<$F22+$G22),1,"") | S22: =IF(AND(7>=$F22,7<$F22+$G22),1,"") | T22: =IF(AND(8>=$F22,8<$F22+$G22),1,"") | U22: =IF(AND(9>=$F22,9<$F22+$G22),1,"") | V22: =IF(AND(10>=$F22,10<$F22+$G22),1,"") | W22: =IF(AND(11>=$F22,11<$F22+$G22),1,"") | X22: =IF(AND(12>=$F22,12<$F22+$G22),1,"") | Y22: =IF(AND(13>=$F22,13<$F22+$G22),1,"") | Z22: =IF(AND(14>=$F22,14<$F22+$G22),1,"")
A23: 2.10 | B23: 2 | C23: Báo cáo | D23: Slide và báo cáo lần 2 (sườn cơ bản) | E23: Hạnh | F23: 5 | G23: 1 | H23: ='Tổng quan'!$C$4+7*(F23-1) | I23: =H23+7*G23-1 | J23: Slide lần 2 | K23: Hoàn thành | M23: =IF(AND(1>=$F23,1<$F23+$G23),1,"") | N23: =IF(AND(2>=$F23,2<$F23+$G23),1,"") | O23: =IF(AND(3>=$F23,3<$F23+$G23),1,"") | P23: =IF(AND(4>=$F23,4<$F23+$G23),1,"") | Q23: =IF(AND(5>=$F23,5<$F23+$G23),1,"") | R23: =IF(AND(6>=$F23,6<$F23+$G23),1,"") | S23: =IF(AND(7>=$F23,7<$F23+$G23),1,"") | T23: =IF(AND(8>=$F23,8<$F23+$G23),1,"") | U23: =IF(AND(9>=$F23,9<$F23+$G23),1,"") | V23: =IF(AND(10>=$F23,10<$F23+$G23),1,"") | W23: =IF(AND(11>=$F23,11<$F23+$G23),1,"") | X23: =IF(AND(12>=$F23,12<$F23+$G23),1,"") | Y23: =IF(AND(13>=$F23,13<$F23+$G23),1,"") | Z23: =IF(AND(14>=$F23,14<$F23+$G23),1,"")
A24: Đợt 3 · Mua vé, AI chatbox, admin dashboard
A25: 3.1 | B25: 3 | C25: Backend | D25: Luồng mua vé: ordering saga, thanh toán payOS (webhook có ký), sổ cái kép, phát vé QR | E25: Thiện | F25: 6 | G25: 2 | H25: ='Tổng quan'!$C$4+7*(F25-1) | I25: =H25+7*G25-1 | J25: ordering, payment, ledger, ticketing service | K25: Hoàn thành | L25: backend/services/ordering|payment|ledger|ticketing-service | M25: =IF(AND(1>=$F25,1<$F25+$G25),1,"") | N25: =IF(AND(2>=$F25,2<$F25+$G25),1,"") | O25: =IF(AND(3>=$F25,3<$F25+$G25),1,"") | P25: =IF(AND(4>=$F25,4<$F25+$G25),1,"") | Q25: =IF(AND(5>=$F25,5<$F25+$G25),1,"") | R25: =IF(AND(6>=$F25,6<$F25+$G25),1,"") | S25: =IF(AND(7>=$F25,7<$F25+$G25),1,"") | T25: =IF(AND(8>=$F25,8<$F25+$G25),1,"") | U25: =IF(AND(9>=$F25,9<$F25+$G25),1,"") | V25: =IF(AND(10>=$F25,10<$F25+$G25),1,"") | W25: =IF(AND(11>=$F25,11<$F25+$G25),1,"") | X25: =IF(AND(12>=$F25,12<$F25+$G25),1,"") | Y25: =IF(AND(13>=$F25,13<$F25+$G25),1,"") | Z25: =IF(AND(14>=$F25,14<$F25+$G25),1,"")
A26: 3.2 | B26: 3 | C26: Backend | D26: realtime-gateway (WebSocket sơ đồ ghế), notification-service (email) | E26: Thiện | F26: 7 | G26: 1 | H26: ='Tổng quan'!$C$4+7*(F26-1) | I26: =H26+7*G26-1 | J26: Cập nhật ghế realtime, email vé | K26: Hoàn thành | L26: backend/services/realtime-gateway, notification-service | M26: =IF(AND(1>=$F26,1<$F26+$G26),1,"") | N26: =IF(AND(2>=$F26,2<$F26+$G26),1,"") | O26: =IF(AND(3>=$F26,3<$F26+$G26),1,"") | P26: =IF(AND(4>=$F26,4<$F26+$G26),1,"") | Q26: =IF(AND(5>=$F26,5<$F26+$G26),1,"") | R26: =IF(AND(6>=$F26,6<$F26+$G26),1,"") | S26: =IF(AND(7>=$F26,7<$F26+$G26),1,"") | T26: =IF(AND(8>=$F26,8<$F26+$G26),1,"") | U26: =IF(AND(9>=$F26,9<$F26+$G26),1,"") | V26: =IF(AND(10>=$F26,10<$F26+$G26),1,"") | W26: =IF(AND(11>=$F26,11<$F26+$G26),1,"") | X26: =IF(AND(12>=$F26,12<$F26+$G26),1,"") | Y26: =IF(AND(13>=$F26,13<$F26+$G26),1,"") | Z26: =IF(AND(14>=$F26,14<$F26+$G26),1,"")
A27: 3.3 | B27: 3 | C27: AI | D27: ai-chatbox-service: RAG với pgvector, kho tri thức, nhúng Ollama/Voyage, LLM Anthropic/Ollama | E27: Thiện | F27: 6 | G27: 2 | H27: ='Tổng quan'!$C$4+7*(F27-1) | I27: =H27+7*G27-1 | J27: Chatbot trả lời theo tri thức | K27: Hoàn thành | L27: backend/services/ai-chatbox-service | M27: =IF(AND(1>=$F27,1<$F27+$G27),1,"") | N27: =IF(AND(2>=$F27,2<$F27+$G27),1,"") | O27: =IF(AND(3>=$F27,3<$F27+$G27),1,"") | P27: =IF(AND(4>=$F27,4<$F27+$G27),1,"") | Q27: =IF(AND(5>=$F27,5<$F27+$G27),1,"") | R27: =IF(AND(6>=$F27,6<$F27+$G27),1,"") | S27: =IF(AND(7>=$F27,7<$F27+$G27),1,"") | T27: =IF(AND(8>=$F27,8<$F27+$G27),1,"") | U27: =IF(AND(9>=$F27,9<$F27+$G27),1,"") | V27: =IF(AND(10>=$F27,10<$F27+$G27),1,"") | W27: =IF(AND(11>=$F27,11<$F27+$G27),1,"") | X27: =IF(AND(12>=$F27,12<$F27+$G27),1,"") | Y27: =IF(AND(13>=$F27,13<$F27+$G27),1,"") | Z27: =IF(AND(14>=$F27,14<$F27+$G27),1,"")
A28: 3.4 | B28: 3 | C28: AI | D28: Chatbot gọi công cụ (tra đơn, sự kiện), chuyển nhân viên, kiểm câu trả lời có nguồn | E28: Thiện | F28: 7 | G28: 2 | H28: ='Tổng quan'!$C$4+7*(F28-1) | I28: =H28+7*G28-1 | J28: Tool-calling, handoff, grounding | K28: Hoàn thành | L28: ai-chatbox-service/application/agent, handoff | M28: =IF(AND(1>=$F28,1<$F28+$G28),1,"") | N28: =IF(AND(2>=$F28,2<$F28+$G28),1,"") | O28: =IF(AND(3>=$F28,3<$F28+$G28),1,"") | P28: =IF(AND(4>=$F28,4<$F28+$G28),1,"") | Q28: =IF(AND(5>=$F28,5<$F28+$G28),1,"") | R28: =IF(AND(6>=$F28,6<$F28+$G28),1,"") | S28: =IF(AND(7>=$F28,7<$F28+$G28),1,"") | T28: =IF(AND(8>=$F28,8<$F28+$G28),1,"") | U28: =IF(AND(9>=$F28,9<$F28+$G28),1,"") | V28: =IF(AND(10>=$F28,10<$F28+$G28),1,"") | W28: =IF(AND(11>=$F28,11<$F28+$G28),1,"") | X28: =IF(AND(12>=$F28,12<$F28+$G28),1,"") | Y28: =IF(AND(13>=$F28,13<$F28+$G28),1,"") | Z28: =IF(AND(14>=$F28,14<$F28+$G28),1,"")
A29: 3.5 | B29: 3 | C29: Kiểm thử | D29: Test tích hợp luồng tiền: saga, webhook payOS, sổ cái bất biến | E29: Thiện | F29: 8 | G29: 1 | H29: ='Tổng quan'!$C$4+7*(F29-1) | I29: =H29+7*G29-1 | J29: CheckoutSagaIT, PayosPaymentFlowIT, LedgerInvariantIT | K29: Hoàn thành | L29: backend/services/*/src/test | M29: =IF(AND(1>=$F29,1<$F29+$G29),1,"") | N29: =IF(AND(2>=$F29,2<$F29+$G29),1,"") | O29: =IF(AND(3>=$F29,3<$F29+$G29),1,"") | P29: =IF(AND(4>=$F29,4<$F29+$G29),1,"") | Q29: =IF(AND(5>=$F29,5<$F29+$G29),1,"") | R29: =IF(AND(6>=$F29,6<$F29+$G29),1,"") | S29: =IF(AND(7>=$F29,7<$F29+$G29),1,"") | T29: =IF(AND(8>=$F29,8<$F29+$G29),1,"") | U29: =IF(AND(9>=$F29,9<$F29+$G29),1,"") | V29: =IF(AND(10>=$F29,10<$F29+$G29),1,"") | W29: =IF(AND(11>=$F29,11<$F29+$G29),1,"") | X29: =IF(AND(12>=$F29,12<$F29+$G29),1,"") | Y29: =IF(AND(13>=$F29,13<$F29+$G29),1,"") | Z29: =IF(AND(14>=$F29,14<$F29+$G29),1,"")
A30: 3.6 | B30: 3 | C30: Frontend | D30: Web khách hàng: chọn ghế, thanh toán, vé của tôi; khung chat hỗ trợ | E30: Hạnh | F30: 6 | G30: 2 | H30: ='Tổng quan'!$C$4+7*(F30-1) | I30: =H30+7*G30-1 | J30: SeatPicker, PaymentPanel, SupportChat | K30: Hoàn thành | L30: frontend/apps/web-customer/src/components | M30: =IF(AND(1>=$F30,1<$F30+$G30),1,"") | N30: =IF(AND(2>=$F30,2<$F30+$G30),1,"") | O30: =IF(AND(3>=$F30,3<$F30+$G30),1,"") | P30: =IF(AND(4>=$F30,4<$F30+$G30),1,"") | Q30: =IF(AND(5>=$F30,5<$F30+$G30),1,"") | R30: =IF(AND(6>=$F30,6<$F30+$G30),1,"") | S30: =IF(AND(7>=$F30,7<$F30+$G30),1,"") | T30: =IF(AND(8>=$F30,8<$F30+$G30),1,"") | U30: =IF(AND(9>=$F30,9<$F30+$G30),1,"") | V30: =IF(AND(10>=$F30,10<$F30+$G30),1,"") | W30: =IF(AND(11>=$F30,11<$F30+$G30),1,"") | X30: =IF(AND(12>=$F30,12<$F30+$G30),1,"") | Y30: =IF(AND(13>=$F30,13<$F30+$G30),1,"") | Z30: =IF(AND(14>=$F30,14<$F30+$G30),1,"")
A31: 3.7 | B31: 3 | C31: Frontend | D31: Sửa giao diện admin dashboard: tổng quan, doanh thu, trình sửa sơ đồ ghế | E31: Hạnh | F31: 7 | G31: 2 | H31: ='Tổng quan'!$C$4+7*(F31-1) | I31: =H31+7*G31-1 | J31: Dashboard mới, FloorPlanEditor | K31: Hoàn thành | L31: frontend/apps/web-admin | M31: =IF(AND(1>=$F31,1<$F31+$G31),1,"") | N31: =IF(AND(2>=$F31,2<$F31+$G31),1,"") | O31: =IF(AND(3>=$F31,3<$F31+$G31),1,"") | P31: =IF(AND(4>=$F31,4<$F31+$G31),1,"") | Q31: =IF(AND(5>=$F31,5<$F31+$G31),1,"") | R31: =IF(AND(6>=$F31,6<$F31+$G31),1,"") | S31: =IF(AND(7>=$F31,7<$F31+$G31),1,"") | T31: =IF(AND(8>=$F31,8<$F31+$G31),1,"") | U31: =IF(AND(9>=$F31,9<$F31+$G31),1,"") | V31: =IF(AND(10>=$F31,10<$F31+$G31),1,"") | W31: =IF(AND(11>=$F31,11<$F31+$G31),1,"") | X31: =IF(AND(12>=$F31,12<$F31+$G31),1,"") | Y31: =IF(AND(13>=$F31,13<$F31+$G31),1,"") | Z31: =IF(AND(14>=$F31,14<$F31+$G31),1,"")
A32: 3.8 | B32: 3 | C32: Frontend | D32: Web quản trị nền tảng (kho tri thức AI, phiếu chuyển nhân viên) và web soát vé | E32: Hạnh | F32: 8 | G32: 1 | H32: ='Tổng quan'!$C$4+7*(F32-1) | I32: =H32+7*G32-1 | J32: web-platform, web-scanner | K32: Hoàn thành | L32: frontend/apps/web-platform, web-scanner | M32: =IF(AND(1>=$F32,1<$F32+$G32),1,"") | N32: =IF(AND(2>=$F32,2<$F32+$G32),1,"") | O32: =IF(AND(3>=$F32,3<$F32+$G32),1,"") | P32: =IF(AND(4>=$F32,4<$F32+$G32),1,"") | Q32: =IF(AND(5>=$F32,5<$F32+$G32),1,"") | R32: =IF(AND(6>=$F32,6<$F32+$G32),1,"") | S32: =IF(AND(7>=$F32,7<$F32+$G32),1,"") | T32: =IF(AND(8>=$F32,8<$F32+$G32),1,"") | U32: =IF(AND(9>=$F32,9<$F32+$G32),1,"") | V32: =IF(AND(10>=$F32,10<$F32+$G32),1,"") | W32: =IF(AND(11>=$F32,11<$F32+$G32),1,"") | X32: =IF(AND(12>=$F32,12<$F32+$G32),1,"") | Y32: =IF(AND(13>=$F32,13<$F32+$G32),1,"") | Z32: =IF(AND(14>=$F32,14<$F32+$G32),1,"")
A33: 3.9 | B33: 3 | C33: Báo cáo | D33: Slide và báo cáo lần 3 (AI chatbox, dashboard) | E33: Hạnh | F33: 8 | G33: 1 | H33: ='Tổng quan'!$C$4+7*(F33-1) | I33: =H33+7*G33-1 | J33: Slide lần 3 | K33: Hoàn thành | M33: =IF(AND(1>=$F33,1<$F33+$G33),1,"") | N33: =IF(AND(2>=$F33,2<$F33+$G33),1,"") | O33: =IF(AND(3>=$F33,3<$F33+$G33),1,"") | P33: =IF(AND(4>=$F33,4<$F33+$G33),1,"") | Q33: =IF(AND(5>=$F33,5<$F33+$G33),1,"") | R33: =IF(AND(6>=$F33,6<$F33+$G33),1,"") | S33: =IF(AND(7>=$F33,7<$F33+$G33),1,"") | T33: =IF(AND(8>=$F33,8<$F33+$G33),1,"") | U33: =IF(AND(9>=$F33,9<$F33+$G33),1,"") | V33: =IF(AND(10>=$F33,10<$F33+$G33),1,"") | W33: =IF(AND(11>=$F33,11<$F33+$G33),1,"") | X33: =IF(AND(12>=$F33,12<$F33+$G33),1,"") | Y33: =IF(AND(13>=$F33,13<$F33+$G33),1,"") | Z33: =IF(AND(14>=$F33,14<$F33+$G33),1,"")
A34: Đợt 4 · Mobile, xuất xlsx, deploy
A35: 4.1 | B35: 4 | C35: Mobile | D35: App khách hàng (Expo): đặt vé, thanh toán, vé, tài khoản | E35: Hạnh | F35: 9 | G35: 2 | H35: ='Tổng quan'!$C$4+7*(F35-1) | I35: =H35+7*G35-1 | J35: mobile-customer | K35: Hoàn thành | L35: frontend/apps/mobile-customer | M35: =IF(AND(1>=$F35,1<$F35+$G35),1,"") | N35: =IF(AND(2>=$F35,2<$F35+$G35),1,"") | O35: =IF(AND(3>=$F35,3<$F35+$G35),1,"") | P35: =IF(AND(4>=$F35,4<$F35+$G35),1,"") | Q35: =IF(AND(5>=$F35,5<$F35+$G35),1,"") | R35: =IF(AND(6>=$F35,6<$F35+$G35),1,"") | S35: =IF(AND(7>=$F35,7<$F35+$G35),1,"") | T35: =IF(AND(8>=$F35,8<$F35+$G35),1,"") | U35: =IF(AND(9>=$F35,9<$F35+$G35),1,"") | V35: =IF(AND(10>=$F35,10<$F35+$G35),1,"") | W35: =IF(AND(11>=$F35,11<$F35+$G35),1,"") | X35: =IF(AND(12>=$F35,12<$F35+$G35),1,"") | Y35: =IF(AND(13>=$F35,13<$F35+$G35),1,"") | Z35: =IF(AND(14>=$F35,14<$F35+$G35),1,"")
A36: 4.2 | B36: 4 | C36: Mobile | D36: App soát vé (camera), soát vào/ra/vào lại, mời nhân viên soát vé | E36: Hạnh | F36: 10 | G36: 2 | H36: ='Tổng quan'!$C$4+7*(F36-1) | I36: =H36+7*G36-1 | J36: mobile-scanner | K36: Hoàn thành | L36: frontend/apps/mobile-scanner | M36: =IF(AND(1>=$F36,1<$F36+$G36),1,"") | N36: =IF(AND(2>=$F36,2<$F36+$G36),1,"") | O36: =IF(AND(3>=$F36,3<$F36+$G36),1,"") | P36: =IF(AND(4>=$F36,4<$F36+$G36),1,"") | Q36: =IF(AND(5>=$F36,5<$F36+$G36),1,"") | R36: =IF(AND(6>=$F36,6<$F36+$G36),1,"") | S36: =IF(AND(7>=$F36,7<$F36+$G36),1,"") | T36: =IF(AND(8>=$F36,8<$F36+$G36),1,"") | U36: =IF(AND(9>=$F36,9<$F36+$G36),1,"") | V36: =IF(AND(10>=$F36,10<$F36+$G36),1,"") | W36: =IF(AND(11>=$F36,11<$F36+$G36),1,"") | X36: =IF(AND(12>=$F36,12<$F36+$G36),1,"") | Y36: =IF(AND(13>=$F36,13<$F36+$G36),1,"") | Z36: =IF(AND(14>=$F36,14<$F36+$G36),1,"")
A37: 4.3 | B37: 4 | C37: Mobile | D37: App ban tổ chức và app quản trị nền tảng | E37: Hạnh | F37: 10 | G37: 2 | H37: ='Tổng quan'!$C$4+7*(F37-1) | I37: =H37+7*G37-1 | J37: mobile-organizer, mobile-platform | K37: Đang làm | L37: frontend/apps/mobile-organizer (2 màn hình) | M37: =IF(AND(1>=$F37,1<$F37+$G37),1,"") | N37: =IF(AND(2>=$F37,2<$F37+$G37),1,"") | O37: =IF(AND(3>=$F37,3<$F37+$G37),1,"") | P37: =IF(AND(4>=$F37,4<$F37+$G37),1,"") | Q37: =IF(AND(5>=$F37,5<$F37+$G37),1,"") | R37: =IF(AND(6>=$F37,6<$F37+$G37),1,"") | S37: =IF(AND(7>=$F37,7<$F37+$G37),1,"") | T37: =IF(AND(8>=$F37,8<$F37+$G37),1,"") | U37: =IF(AND(9>=$F37,9<$F37+$G37),1,"") | V37: =IF(AND(10>=$F37,10<$F37+$G37),1,"") | W37: =IF(AND(11>=$F37,11<$F37+$G37),1,"") | X37: =IF(AND(12>=$F37,12<$F37+$G37),1,"") | Y37: =IF(AND(13>=$F37,13<$F37+$G37),1,"") | Z37: =IF(AND(14>=$F37,14<$F37+$G37),1,"")
A38: 4.4 | B38: 4 | C38: Backend | D38: API cho app mobile (suất soát vé, lời mời), thống kê ban tổ chức | E38: Thiện | F38: 9 | G38: 2 | H38: ='Tổng quan'!$C$4+7*(F38-1) | I38: =H38+7*G38-1 | J38: Endpoint mới, analytics | K38: Hoàn thành | L38: backend/services/analytics-service | M38: =IF(AND(1>=$F38,1<$F38+$G38),1,"") | N38: =IF(AND(2>=$F38,2<$F38+$G38),1,"") | O38: =IF(AND(3>=$F38,3<$F38+$G38),1,"") | P38: =IF(AND(4>=$F38,4<$F38+$G38),1,"") | Q38: =IF(AND(5>=$F38,5<$F38+$G38),1,"") | R38: =IF(AND(6>=$F38,6<$F38+$G38),1,"") | S38: =IF(AND(7>=$F38,7<$F38+$G38),1,"") | T38: =IF(AND(8>=$F38,8<$F38+$G38),1,"") | U38: =IF(AND(9>=$F38,9<$F38+$G38),1,"") | V38: =IF(AND(10>=$F38,10<$F38+$G38),1,"") | W38: =IF(AND(11>=$F38,11<$F38+$G38),1,"") | X38: =IF(AND(12>=$F38,12<$F38+$G38),1,"") | Y38: =IF(AND(13>=$F38,13<$F38+$G38),1,"") | Z38: =IF(AND(14>=$F38,14<$F38+$G38),1,"")
A39: 4.5 | B39: 4 | C39: Backend | D39: API dữ liệu báo cáo để xuất xlsx (doanh thu, vé, soát vé) | E39: Thiện | F39: 10 | G39: 1 | H39: ='Tổng quan'!$C$4+7*(F39-1) | I39: =H39+7*G39-1 | J39: Endpoint báo cáo | K39: Chưa làm | L39: Hiện chỉ xuất CSV: frontend/packages/ui/src/csv.ts | M39: =IF(AND(1>=$F39,1<$F39+$G39),1,"") | N39: =IF(AND(2>=$F39,2<$F39+$G39),1,"") | O39: =IF(AND(3>=$F39,3<$F39+$G39),1,"") | P39: =IF(AND(4>=$F39,4<$F39+$G39),1,"") | Q39: =IF(AND(5>=$F39,5<$F39+$G39),1,"") | R39: =IF(AND(6>=$F39,6<$F39+$G39),1,"") | S39: =IF(AND(7>=$F39,7<$F39+$G39),1,"") | T39: =IF(AND(8>=$F39,8<$F39+$G39),1,"") | U39: =IF(AND(9>=$F39,9<$F39+$G39),1,"") | V39: =IF(AND(10>=$F39,10<$F39+$G39),1,"") | W39: =IF(AND(11>=$F39,11<$F39+$G39),1,"") | X39: =IF(AND(12>=$F39,12<$F39+$G39),1,"") | Y39: =IF(AND(13>=$F39,13<$F39+$G39),1,"") | Z39: =IF(AND(14>=$F39,14<$F39+$G39),1,"")
A40: 4.6 | B40: 4 | C40: Frontend | D40: Nút xuất báo cáo .xlsx trên web quản trị | E40: Hạnh | F40: 11 | G40: 1 | H40: ='Tổng quan'!$C$4+7*(F40-1) | I40: =H40+7*G40-1 | J40: File .xlsx tải về | K40: Chưa làm | L40: Hiện chỉ xuất CSV | M40: =IF(AND(1>=$F40,1<$F40+$G40),1,"") | N40: =IF(AND(2>=$F40,2<$F40+$G40),1,"") | O40: =IF(AND(3>=$F40,3<$F40+$G40),1,"") | P40: =IF(AND(4>=$F40,4<$F40+$G40),1,"") | Q40: =IF(AND(5>=$F40,5<$F40+$G40),1,"") | R40: =IF(AND(6>=$F40,6<$F40+$G40),1,"") | S40: =IF(AND(7>=$F40,7<$F40+$G40),1,"") | T40: =IF(AND(8>=$F40,8<$F40+$G40),1,"") | U40: =IF(AND(9>=$F40,9<$F40+$G40),1,"") | V40: =IF(AND(10>=$F40,10<$F40+$G40),1,"") | W40: =IF(AND(11>=$F40,11<$F40+$G40),1,"") | X40: =IF(AND(12>=$F40,12<$F40+$G40),1,"") | Y40: =IF(AND(13>=$F40,13<$F40+$G40),1,"") | Z40: =IF(AND(14>=$F40,14<$F40+$G40),1,"")
...

Sheet Báo cáo
A1: LỊCH VÀ NỘI DUNG CÁC BUỔI BÁO CÁO
A3: Lần | B3: Tuần | C3: Ngày báo cáo | D3: Cách lần trước (tuần) | E3: Nội dung báo cáo | F3: Người trình bày | G3: Demo / sản phẩm mang đi | H3: Số việc của đợt | I3: Đã xong | J3: Tiến độ
A4: 1 | B4: 3 | C4: ='Tổng quan'!$C$4+7*(B4-1) | E4: Timeline dự án, kiến trúc dự án; thầy hướng dẫn phần AI cần làm | F4: Thiện (kiến trúc, AI) · Hạnh (timeline, slide) | G4: Slide timeline + sơ đồ kiến trúc microservices, ERD, đề xuất hướng AI | H4: =COUNTIF('Kế hoạch'!$B:$B,A4) | I4: =COUNTIFS('Kế hoạch'!$B:$B,A4,'Kế hoạch'!$K:$K,"Hoàn thành") | J4: =IF(H4=0,"-",I4/H4)
A5: 2 | B5: 6 | C5: ='Tổng quan'!$C$4+7*(B5-1) | D5: =B5-B4 | E5: Sườn cơ bản của dự án | F5: Thiện (backend) · Hạnh (frontend) | G5: Chạy local: đăng nhập Keycloak, tạo sự kiện, giữ ghế; khung web khách hàng và web quản trị | H5: =COUNTIF('Kế hoạch'!$B:$B,A5) | I5: =COUNTIFS('Kế hoạch'!$B:$B,A5,'Kế hoạch'!$K:$K,"Hoàn thành") | J5: =IF(H5=0,"-",I5/H5)
A6: 3 | B6: 9 | C6: ='Tổng quan'!$C$4+7*(B6-1) | D6: =B6-B5 | E6: AI chatbox hỗ trợ người dùng; sửa giao diện admin dashboard | F6: Thiện (AI chatbox) · Hạnh (admin dashboard) | G6: Demo hỏi đáp RAG, tra đơn, chuyển nhân viên; dashboard doanh thu mới | H6: =COUNTIF('Kế hoạch'!$B:$B,A6) | I6: =COUNTIFS('Kế hoạch'!$B:$B,A6,'Kế hoạch'!$K:$K,"Hoàn thành") | J6: =IF(H6=0,"-",I6/H6)
A7: 4 | B7: 12 | C7: ='Tổng quan'!$C$4+7*(B7-1) | D7: =B7-B6 | E7: Demo mobile app; xuất file xlsx | F7: Hạnh (mobile) · Thiện (API, xuất xlsx) | G7: App khách hàng + app soát vé trên điện thoại; tải báo cáo .xlsx từ trang quản trị | H7: =COUNTIF('Kế hoạch'!$B:$B,A7) | I7: =COUNTIFS('Kế hoạch'!$B:$B,A7,'Kế hoạch'!$K:$K,"Hoàn thành") | J7: =IF(H7=0,"-",I7/H7)
A8: 5 | B8: 15 | C8: ='Tổng quan'!$C$4+7*(B8-1) | D8: =B8-B7 | E8: Tổng kết, nghiệm thu, chuẩn bị bảo vệ (đề xuất) | F8: Cả hai | G8: Demo toàn luồng trên production; quyển báo cáo; kết quả kiểm thử | H8: =COUNTIF('Kế hoạch'!$B:$B,A8) | I8: =COUNTIFS('Kế hoạch'!$B:$B,A8,'Kế hoạch'!$K:$K,"Hoàn thành") | J8: =IF(H8=0,"-",I8/H8)
A10: Ghi chú
A11: Lần 1: báo cáo timeline và kiến trúc; sau buổi này thầy hướng dẫn phạm vi phần AI, kết quả được đưa vào Đợt 3 (AI chatbox).
A12: Lần 4 'xuất ra file xlsx' được hiểu là chức năng xuất báo cáo .xlsx trên web quản trị (hiện hệ thống mới xuất CSV).

Sheet Phân công
A1: PHÂN CÔNG THEO THÀNH VIÊN
A3: Phụ trách | B3: Tổng việc | C3: Hoàn thành | D3: Đang làm | E3: Chưa làm | F3: Tổng tuần-công | G3: Tỉ lệ xong
A4: Thiện | B4: =COUNTIF('Kế hoạch'!$E:$E,A4) | C4: =COUNTIFS('Kế hoạch'!$E:$E,A4,'Kế hoạch'!$K:$K,"Hoàn thành") | D4: =COUNTIFS('Kế hoạch'!$E:$E,A4,'Kế hoạch'!$K:$K,"Đang làm") | E4: =COUNTIFS('Kế hoạch'!$E:$E,A4,'Kế hoạch'!$K:$K,"Chưa làm") | F4: =SUMIF('Kế hoạch'!$E:$E,A4,'Kế hoạch'!$G:$G) | G4: =IF(B4=0,"-",C4/B4)
A5: Hạnh | B5: =COUNTIF('Kế hoạch'!$E:$E,A5) | C5: =COUNTIFS('Kế hoạch'!$E:$E,A5,'Kế hoạch'!$K:$K,"Hoàn thành") | D5: =COUNTIFS('Kế hoạch'!$E:$E,A5,'Kế hoạch'!$K:$K,"Đang làm") | E5: =COUNTIFS('Kế hoạch'!$E:$E,A5,'Kế hoạch'!$K:$K,"Chưa làm") | F5: =SUMIF('Kế hoạch'!$E:$E,A5,'Kế hoạch'!$G:$G) | G5: =IF(B5=0,"-",C5/B5)
A6: Cả hai | B6: =COUNTIF('Kế hoạch'!$E:$E,A6) | C6: =COUNTIFS('Kế hoạch'!$E:$E,A6,'Kế hoạch'!$K:$K,"Hoàn thành") | D6: =COUNTIFS('Kế hoạch'!$E:$E,A6,'Kế hoạch'!$K:$K,"Đang làm") | E6: =COUNTIFS('Kế hoạch'!$E:$E,A6,'Kế hoạch'!$K:$K,"Chưa làm") | F6: =SUMIF('Kế hoạch'!$E:$E,A6,'Kế hoạch'!$G:$G) | G6: =IF(B6=0,"-",C6/B6)
A7: Tổng | B7: =SUM(B4:B6) | C7: =SUM(C4:C6) | D7: =SUM(D4:D6) | E7: =SUM(E4:E6) | F7: =SUM(F4:F6) | G7: =IF(B7=0,"-",C7/B7)
A10: Việc theo hạng mục
A11: Hạng mục | B11: Thiện | C11: Hạnh | D11: Cả hai
A12: AI | B12: =COUNTIFS('Kế hoạch'!$C:$C,$A12,'Kế hoạch'!$E:$E,"Thiện") | C12: =COUNTIFS('Kế hoạch'!$C:$C,$A12,'Kế hoạch'!$E:$E,"Hạnh") | D12: =COUNTIFS('Kế hoạch'!$C:$C,$A12,'Kế hoạch'!$E:$E,"Cả hai")
A13: Backend | B13: =COUNTIFS('Kế hoạch'!$C:$C,$A13,'Kế hoạch'!$E:$E,"Thiện") | C13: =COUNTIFS('Kế hoạch'!$C:$C,$A13,'Kế hoạch'!$E:$E,"Hạnh") | D13: =COUNTIFS('Kế hoạch'!$C:$C,$A13,'Kế hoạch'!$E:$E,"Cả hai")
A14: Báo cáo | B14: =COUNTIFS('Kế hoạch'!$C:$C,$A14,'Kế hoạch'!$E:$E,"Thiện") | C14: =COUNTIFS('Kế hoạch'!$C:$C,$A14,'Kế hoạch'!$E:$E,"Hạnh") | D14: =COUNTIFS('Kế hoạch'!$C:$C,$A14,'Kế hoạch'!$E:$E,"Cả hai")
A15: CSDL | B15: =COUNTIFS('Kế hoạch'!$C:$C,$A15,'Kế hoạch'!$E:$E,"Thiện") | C15: =COUNTIFS('Kế hoạch'!$C:$C,$A15,'Kế hoạch'!$E:$E,"Hạnh") | D15: =COUNTIFS('Kế hoạch'!$C:$C,$A15,'Kế hoạch'!$E:$E,"Cả hai")
A16: Frontend | B16: =COUNTIFS('Kế hoạch'!$C:$C,$A16,'Kế hoạch'!$E:$E,"Thiện") | C16: =COUNTIFS('Kế hoạch'!$C:$C,$A16,'Kế hoạch'!$E:$E,"Hạnh") | D16: =COUNTIFS('Kế hoạch'!$C:$C,$A16,'Kế hoạch'!$E:$E,"Cả hai")
A17: Giao diện | B17: =COUNTIFS('Kế hoạch'!$C:$C,$A17,'Kế hoạch'!$E:$E,"Thiện") | C17: =COUNTIFS('Kế hoạch'!$C:$C,$A17,'Kế hoạch'!$E:$E,"Hạnh") | D17: =COUNTIFS('Kế hoạch'!$C:$C,$A17,'Kế hoạch'!$E:$E,"Cả hai")
A18: Hạ tầng | B18: =COUNTIFS('Kế hoạch'!$C:$C,$A18,'Kế hoạch'!$E:$E,"Thiện") | C18: =COUNTIFS('Kế hoạch'!$C:$C,$A18,'Kế hoạch'!$E:$E,"Hạnh") | D18: =COUNTIFS('Kế hoạch'!$C:$C,$A18,'Kế hoạch'!$E:$E,"Cả hai")
A19: Kiến trúc | B19: =COUNTIFS('Kế hoạch'!$C:$C,$A19,'Kế hoạch'!$E:$E,"Thiện") | C19: =COUNTIFS('Kế hoạch'!$C:$C,$A19,'Kế hoạch'!$E:$E,"Hạnh") | D19: =COUNTIFS('Kế hoạch'!$C:$C,$A19,'Kế hoạch'!$E:$E,"Cả hai")
A20: Kiểm thử | B20: =COUNTIFS('Kế hoạch'!$C:$C,$A20,'Kế hoạch'!$E:$E,"Thiện") | C20: =COUNTIFS('Kế hoạch'!$C:$C,$A20,'Kế hoạch'!$E:$E,"Hạnh") | D20: =COUNTIFS('Kế hoạch'!$C:$C,$A20,'Kế hoạch'!$E:$E,"Cả hai")
A21: Mobile | B21: =COUNTIFS('Kế hoạch'!$C:$C,$A21,'Kế hoạch'!$E:$E,"Thiện") | C21: =COUNTIFS('Kế hoạch'!$C:$C,$A21,'Kế hoạch'!$E:$E,"Hạnh") | D21: =COUNTIFS('Kế hoạch'!$C:$C,$A21,'Kế hoạch'!$E:$E,"Cả hai")
A22: Phân tích | B22: =COUNTIFS('Kế hoạch'!$C:$C,$A22,'Kế hoạch'!$E:$E,"Thiện") | C22: =COUNTIFS('Kế hoạch'!$C:$C,$A22,'Kế hoạch'!$E:$E,"Hạnh") | D22: =COUNTIFS('Kế hoạch'!$C:$C,$A22,'Kế hoạch'!$E:$E,"Cả hai")
